Workbook
Name A: '4'!$XEO$2:$XEP$2

Sheet 1
A1: 【 醫療機構、藥局 】(第 四 級管制藥品)
A2: 藥代：ALPR | B2: 管 制 藥 品 收 支 結 存 簿 冊 | J2: 名稱 | K2: 字號 | L2: 上期結存 | M2: 收入 | N2: 支出 | O2: 結存
A3: 藥品名稱 | B3: Gendergin 0.5mg | E3: 管制藥品成分及含量 | H3: Alprazolam 0.5mg | J3: =B3 -> Gendergin 0.5mg | K3: 042514 | L3: 0 | M3: =SUM(C:C) -> 0 | N3: =SUM(F:F) -> 0 | O3: =L3+M3-N3 -> 0
A4: 管制級別 | B4: 四 | E4: 製造廠名稱 | H4: 健亞生物科技(股)公司
A5: 藥品許可證字號 | C5: 衛署藥製字第042514號 | H5: 最小單位 | I5: 粒
A6: 日 期 | B6: 收支原因 | C6: 收入數量 | D6: 收入藥品批號 | F6: 支出數量 | H6: 結存數量 | I6: 備 註
A7: 115/01/01 | B7: 上期結存 | C7: 0 | H7: 0

Sheet 總表
A1: 編號 | B1: 藥代 | C1: 名稱 | D1: 中文名稱 | E1: 字號 | F1: 字號2 | G1: 字號3 | H1: 上期結存 | I1: 收入 | J1: 支出 | K1: 欄5 | L1: 結存 | M1: 效期 (會變色) | N1: 無轉讓* | P1: 江鎰 (QDA10600000101) | Q1: 蔓達特(QDA100000003)
A2: 41 | B2: ALE1 | C2: ='41'!$B$3 -> Alepan 15mg | D2: 安立平 15mg | E2: ='41'!C5 -> 衛署藥製字第046145號 | F2: 衛署藥製字第 | G2: 46145 | H2: ='41'!L3 -> 0 | I2: ='41'!M3 -> 20 | J2: ='41'!N3 -> 14 | K2: 56 | L2: ='41'!O3 -> 6
A3: 70 | B3: ALE2 | C3: ='70'!$B$3 -> Alepam 15mg | D3: 安慮平 15mg | E3: 衛署藥輸字第018425號 | F3: 衛署藥輸字第 | G3: 18425 | H3: ='70'!L3 -> 0 | I3: ='70'!M3 -> 0 | J3: ='70'!N3 -> 0 | L3: ='70'!O3 -> 0 | N3: *
A4: 31 | B4: ALP2 | C4: ='31'!$B$3 -> Alpraline 0.5mg | D4: 安柏寧 0.5mg | E4: ='31'!C5 -> 衛署藥製字第044685號 | F4: 衛署藥製字第 | G4: 44685 | H4: ='31'!L3 -> 443 | I4: ='31'!M3 -> 1000 | J4: ='31'!N3 -> 903.5 | K4: 104 | L4: ='31'!O3 -> 539.5
A5: 1 | B5: 不使用 | C5: ='1'!B3 -> Gendergin 0.5mg | D5: 健得靜 0.5mg | E5: ='1'!C5 -> 衛署藥製字第042514號 | F5: 衛署藥製字第 | G5: 42514 | H5: ='1'!L3 -> 0 | I5: ='1'!M3 -> 0 | J5: ='1'!N3 -> 0 | L5: ='1'!O3 -> 0 | N5: *
A6: 54 | B6: ALPR3 | C6: ='54'!$B$3 -> Vanipen 0.5mg | D6: 煩力平 0.5mg | E6: ='54'!C5 -> 衛署藥製字第044546號 | F6: 衛署藥製字第 | G6: 44546 | H6: ='54'!L3 -> 0 | I6: ='54'!M3 -> 0 | J6: ='54'!N3 -> 0 | L6: ='54'!O3 -> 0 | N6: *
A7: 29 | B7: ALPR4/ALP1 | C7: ='29'!$B$3 -> Alprazolam 0.5mg | D7: 安邦錠 0.5mg | E7: ='29'!C5 -> 衛署藥製字第057740號 | F7: 衛署藥製字第 | G7: 57740 | H7: ='29'!L3 -> 1383.5 | I7: ='29'!M3 -> 6000 | J7: ='29'!N3 -> 5451 | K7: 340.5 | L7: ='29'!O3 -> 1932.5
A8: 78 | B8: ALPR6 | C8: ='78'!$B$3 -> Aprazo 0.5mg | D8: 歐普樂錠 0.5mg | E8: 衛署藥製字第045070號 | F8: 衛署藥製字第 | G8: 45070 | H8: ='78'!L3 -> 94 | I8: ='78'!M3 -> 1580 | J8: ='78'!N3 -> 1242 | L8: ='78'!O3 -> 432 | M8: 47392
A9: 95 | B9: ALPR/ALPR寶 | C9: ='95'!$B$3 -> Alpragin 2mg | D9: 安寶寧 2mg | E9: 衛署藥製字第047961號 | F9: 衛署藥製字第 | G9: 47961 | H9: ='95'!L3 -> 57 | I9: ='95'!M3 -> 0 | J9: ='95'!N3 -> 57 | K9: 30 | L9: ='95'!O3 -> 0 | M9: 46722
A10: 58 | B10: ANX1 | C10: ='58'!$B$3 -> Anxiedin 0.5mg | D10: 安靜錠 0.5mg | E10: ='58'!C5 -> 衛署藥製字第024463號 | F10: 衛署藥製字第 | G10: 24463 | H10: ='58'!L3 -> 64 | I10: ='58'!M3 -> 100 | J10: ='58'!N3 -> 0 | L10: ='58'!O3 -> 164
A11: 94 | B11: ANX8 | C11: ='94'!$B$3 -> Anxicam 2mg | D11: 安心平 2mg | E11: 衛部藥製字第058561號 | F11: 衛部藥製字第 | G11: 58561 | H11: ='94'!K3 -> 22 | I11: ='94'!L3 -> 122 | J11: ='94'!M3 -> 90 | K11: 30 | L11: ='94'!N3 -> 32
A12: 50 | B12: ANX9 | C12: ='50'!$B$3 -> ANXIEDIN 1MG | D12: 安靜錠 1mg | E12: ='50'!C5 -> 衛署藥輸字第024885號 | F12: 衛署藥輸字第 | G12: 24885 | H12: ='50'!L3 -> 28 | I12: 0 | J12: ='50'!N3 -> 1061 | L12: ='50'!O3 -> 107
A13: 22 | B13: APO0 | C13: ='22'!$B$3 -> Apo-Tramadol 37.5mg/ 325mg | D13: 安保舒痛 37.5mg/325mg | E13: ='22'!C5 -> 衛署藥輸字第025452號 | F13: 衛署藥輸字第 | G13: 25452 | H13: ='22'!L3 -> 140 | I13: ='22'!M3 -> 800 | J13: ='22'!N3 -> 956 | K13: 56 | L13: ='22'!O3 -> -16
A14: 27 | B14: APO1 | C14: ='27'!$B$3 -> Apo-Methyphenidate 10mg | D14: 安保美喜 10mg | E14: ='27'!C5 -> 衛署藥輸字第025016號 | F14: 衛署藥輸字第 | G14: 25016 | H14: ='27'!L3 -> 0 | I14: ='27'!M3 -> 0 | J14: ='27'!N3 -> 0 | L14: ='27'!O3 -> 0 | N14: *
A15: 2 | B15: ATIV | C15: ='2'!$B$3 -> Ativan 0.5mg | D15: 安定文 0.5mg | E15: ='2'!C5 -> 衛署藥輸字第018741號 | F15: 衛署藥輸字第 | G15: 18741 | H15: ='2'!L3 -> 608 | I15: ='2'!M3 -> 1000 | J15: ='2'!N3 -> 1102 | K15: 91 | L15: ='2'!O3 -> 506
A16: 93 | B16: BRO6/BROMA3 | C16: ='93'!$B$3 -> Bromazin 3mg | D16: 牟靜錠 3mg | E16: 衛署藥製字第026080號 | F16: 衛署藥製字第 | G16: 26080 | H16: ='93'!L3 -> 2 | I16: ='93'!M3 -> 0 | J16: ='93'!N3 -> 0 | L16: ='93'!O3 -> 2 | M16: 46600
A17: 72 | B17: BRO7/BROAN | C17: ='72'!$B$3 -> Bropan 3mg | D17: 優寧錠 3mg | E17: 衛署藥製字第029503號 | F17: 衛署藥製字第 | G17: 29503 | H17: ='72'!L3 -> 60 | I17: ='72'!M3 -> 60 | J17: ='72'!N3 -> 56 | L17: ='72'!O3 -> 64 | N17: *
A18: 56 | B18: CAL4 | C18: ='56'!$B$3 -> Calmday 5mg | D18: 康眠定 5mg | E18: ='56'!C5 -> 衛署藥輸字第016477號 | F18: 衛署藥輸字第 | G18: 16477 | H18: ='56'!L3 -> 0 | I18: ='56'!M3 -> 0 | J18: ='56'!N3 -> 0 | L18: ='56'!O3 -> 0 | N18: *
A19: 75 | B19: CAM1 | C19: ='75'!$B$3 -> Camadol 50mg | D19: 卡莫德膠囊 50mg | E19: 衛署藥製字第043597號 | F19: 衛署藥製字第 | G19: 43597 | H19: ='75'!L3 -> 0 | I19: ='75'!M3 -> 0 | J19: ='75'!N3 -> 0 | L19: ='75'!O3 -> 0 | N19: *
A20: 7 | B20: CLO1/RIVT/ | C20: ='7'!$B$3 -> Clonazepam 0.5mg | D20: 克癇平 0.5mg | E20: ='7'!C5 -> 衛署藥製字第045342號 | F20: 衛署藥製字第 | G20: 45342 | H20: ='75'!L4 -> 0 | I20: ='7'!M3 -> 300 | J20: ='7'!N3 -> 501 | K20: 14 | L20: ='7'!O3 -> 144.5 | M20: 46266
A21: 80 | B21: CLO4/CLO6 | C21: ='80'!$B$3 -> Clonopam 2mg | D21: 克癇平 2mg | E21: 衛署藥製字第045345號 | F21: 衛署藥製字第 | G21: 45345 | H21: ='80'!L3 -> 78 | I21: ='80'!M3 -> 140 | J21: ='80'!N3 -> 119 | L21: ='80'!O3 -> 99 | M21: 46327
A22: 26 | B22: CON2 | C22: ='26'!$B$3 -> Concerta E.R 18mg | D22: 專思達長效 18mg | E22: ='26'!C5 -> 衛署藥輸字第023731號 | F22: 衛署藥輸字第 | G22: 23731 | H22: ='26'!L3 -> 26 | I22: ='26'!M3 -> 120 | J22: ='26'!N3 -> 120 | K22: 28 | L22: ='26'!O3 -> 26 | M22: 46174
A23: 28 | B23: CON3 | C23: ='28'!$B$3 -> Concerta E.R 36mg | D23: 專思達長效 36mg | E23: ='28'!C5 -> 衛署藥輸字第023880號 | F23: 衛署藥輸字第 | G23: 23880 | H23: ='28'!L3 -> 0 | I23: ='28'!M3 -> 120 | J23: ='28'!N3 -> 120 | K23: 28 | L23: ='28'!O3 -> 0 | N23: *
A24: 61 | B24: CON6 | C24: ='61'!$B$3 -> Concerta E.R 27mg | D24: 專思達長效錠 27mg | E24: ='61'!C5 -> 衛署藥輸字第023999號 | F24: 衛署藥輸字第 | G24: 23999 | H24: ='61'!L3 -> 0 | I24: ='61'!M3 -> 0 | J24: ='61'!N3 -> 0 | L24: ='61'!O3 -> 0 | N24: *
A25: 30 | B25: DAC2 | C25: ='30'!$B$3 -> Dactive 10 mg | D25: 安得眠 10mg | E25: ='30'!C5 -> 衛署藥輸字第024958號 | F25: 衛署藥輸字第 | G25: 24958 | H25: ='30'!L3 -> 0 | I25: ='30'!M3 -> 0 | J25: ='30'!N3 -> 0 | L25: ='30'!O3 -> 0 | N25: *
A26: 45 | B26: DAL | C26: ='45'!$B$3 -> Dalmadorm 30mg | D26: 當眠多 30mg | E26: ='45'!C5 -> 衛署藥製字第036677號 | F26: 衛署藥製字第 | G26: 36677 | H26: ='45'!L3 -> 0 | I26: ='45'!M3 -> 0 | J26: ='45'!N3 -> 0 | K26: 56 | L26: ='45'!O3 -> 0 | N26: *
A27: 66 | B27: DAL1 | C27: ='66'!$B$3 -> Dalmadorm 15mg | D27: 當眠多 15mg | E27: 衛署藥製字第036679號 | F27: 衛署藥製字第 | G27: 36679 | I27: ='66'!M3 -> 0 | J27: ='66'!N3 -> 0 | N27: *
A28: 106 | B28: DGEP3 | D28: "井田"醫嗽寧錠 | E28: 衛署藥製字第019360號 | F28: 衛署藥製字第 | G28: 19360 | H28: ='106'!L3 -> 687 | I28: ='106'!M3 -> 0 | J28: ='106'!N3 -> 385.5 | K28: ='106'!O3 -> 301.5 | L28: ='106'!O3 -> 301.5
A29: 51 | B29: DIA8 | C29: ='51'!$B$3 -> Diapine 2mg | D29: 大安源 2mg | E29: ='51'!C5 -> 內衛藥製字第004875號 | F29: 內衛藥製字第 | G29: 4875 | H29: ='51'!L3 -> 0 | I29: ='51'!M3 -> 0 | J29: ='51'!N3 -> 0 | L29: ='51'!O3 -> 0 | N29: *
A30: 13 | B30: DIAL/DIA1 | C30: ='13'!$B$3 -> Diapin 2mg | D30: 當立平 2mg | E30: ='13'!C5 -> 衛署藥製字第000059號 | F30: 衛署藥製字第 | G30: 59 | H30: ='13'!L3 -> 76 | I30: ='13'!M3 -> 0 | J30: ='13'!N3 -> 28 | L30: ='13'!O3 -> 48 | M30: 46082
A31: 71 | B31: DIP7 | C31: ='71'!$B$3 -> Dipoxido 10mg | D31: 大益神膠囊 10mg | E31: ='71'!C5 -> 內衛藥製字第005038號 | F31: 內衛藥製字第 | G31: 5038 | H31: ='71'!L3 -> 0 | I31: ='71'!M3 -> 0 | J31: ='71'!N3 -> 0 | L31: ='71'!O3 -> 0 | N31: *
A32: 68 | B32: DORM | C32: ='68'!$B$3 -> Dormicum 7.5mg | D32: 導美睡 7.5mg | E32: 衛署藥輸字第017577號 | F32: 衛署藥輸字第 | G32: 17577 | H32: ='68'!L3 -> 41 | I32: ='68'!M3 -> 800 | J32: ='68'!N3 -> 280 | L32: ='68'!O3 -> 561 | M32: 46631
A33: 60 | B33: DUP0 | C33: ='60'!$B$3 -> Dupin 5mg | D33: 樂平片 0.5mg | E33: ='60'!C5 -> 內衛藥製字第010468號 | F33: 內衛藥製字第 | G33: 10468 | H33: ='60'!L3 -> 0 | I33: ='60'!M3 -> 0 | J33: ='60'!N3 -> 0 | L33: ='60'!O3 -> 0
A34: 38 | B34: ELI | C34: ='38'!$B$3 -> Elinin 20mg | D34: 宜利寧 20mg | E34: ='38'!C5 -> 衛署藥製字第031515號 | F34: 衛署藥製字第 | G34: 31515 | H34: ='38'!L3 -> 0 | I34: ='38'!M3 -> 0 | J34: ='38'!N3 -> 0 | L34: ='38'!O3 -> 0 | N34: *
A35: 102 | B35: EPI21 | C35: WEISUFU | D35: 胃舒服錠 | E35: ='102'!C5 -> 衛署藥製字第033157號 | F35: 衛署藥製字第 | G35: 33157 | H35: ='102'!L3 -> 3052 | I35: ='102'!M3 -> 3000 | J35: ='102'!N3 -> 1134 | K35: 1476 | L35: ='102'!O3 -> 4918
A36: 3 | B36: ERA/ ERA2(不使用) | C36: ='3'!$B$3 -> ERA 0.25mg | D36: 易舒 0.25mg | E36: ='3'!C5 -> 衛署藥製字第037577號 | F36: 衛署藥製字第 | G36: 37577 | H36: 8 | I36: ='3'!M3 -> 0 | J36: ='3'!N3 -> 0 | K36: 300 | L36: 0
A37: 59 | B37: ERA-4 /ERI | C37: ='59'!$B$3 -> Erispan-S 0.25mg | D37: 癒利舒盼 0.25mg | E37: ='59'!C5 -> 衛署藥製字第046729號 | F37: 衛署藥製字第 | G37: 46729 | H37: ='59'!L3 -> 860.5 | I37: ='59'!M3 -> 6000 | J37: ='59'!N3 -> 5210 | K37: 86 | L37: ='59'!O3 -> 1650.5
A38: 99 | B38: ESO1 | C38: ='99'!$B$3 -> Esomin 2mg | D38: 益思眠 2mg | E38: ='99'!C5 -> 衛署藥製字第043499號 | F38: 衛署藥製字第 | G38: 43499 | H38: ='99'!L3 -> 4 | I38: ='99'!M3 -> 0 | J38: ='99'!N3 -> 0 | L38: ='99'!O3 -> 4 | M38: 46113
A39: 4 | B39: ESTA/ELA | C39: ='4'!$B$3 -> ELAM 2mg | D39: 易眠錠 2mg | E39: ='4'!C5 -> 衛署藥製字第043860號 | F39: 衛署藥製字第 | G39: 43860 | H39: ='4'!L3 -> 1038.5 | I39: ='4'!M3 -> 0 | J39: ='4'!N3 -> 600 | K39: 102 | L39: ='4'!O3 -> 438.5
A40: 14 | B40: ESZO/ESZ2/ESZ | C40: ='14'!$B$3 -> Eszo 2mg | D40: 艾斯樂 2mg | E40: ='14'!C5 -> 衛署藥製字第042646號 | F40: 衛署藥製字第 | G40: 42646 | H40: ='14'!L3 -> 482.5 | I40: ='14'!M3 -> 1000 | J40: ='14'!N3 -> 1164 | K40: 58 | L40: ='14'!O3 -> 318.5
...

Sheet 異動log
A1: 日期 | B1: 相關編號 | C1: 事件 | D1: 備註
A2: 45146 | B2: 24 | C2: 新增 IMO3 於 IMO2 欄位 | D2: IMO2 (BC18158100) IMO3 (BC181581G0)
A3: 45185 | B3: 36 | C3: 新增 ZOLC 於 ZOL2 欄位 | D3: ZOL2(AC46013100) ZOLC(AC460131G0) | H3: 總表欄位有隱藏
A4: 45201 | B4: 1~10 | C4: 9月以前另存 | H4: 下面的頁籤也有隱藏
A5: 45213 | B5: 36 | C5: 新增 ZOLC 於 ZOL2 欄位 | D5: 消失了 重做一次
A6: 45231 | B6: 79 | C6: 新增 ZOL61 於 ZOL6 欄位 | D6: ZOL6健保碼是中化-若定 ZOL61 才對
A7: 45271 | B7: 102 | C7: 新增 EPI2 胃舒服 | D7: 憑證12/7銷售 12/11收到
A8: 45475 | B8: 105 | C8: 新增 WON
A9: 45845 | B9: 107 | C9: 新增 LEYOUMIAN 10mg

Sheet 2
A1: 【 醫療機構、藥局 】(第 四 級管制藥品) | J1: 久裕CDP10300000802 | K1: 調劑 | L1: 購買
A2: 藥代：ATIV,ATI2 | B2: 管 制 藥 品 收 支 結 存 簿 冊 | J2: 名稱 | K2: 字號 | L2: 上期結存 | M2: 收入 | N2: 支出 | O2: 結存
A3: 藥品名稱 | B3: Ativan 0.5mg | E3: 管制藥品成分及含量 | H3: Lorazepam 0.5mg | K3: 018741 | L3: =H7 -> 608 | M3: =SUM(C$8:C$1048576) -> 1000 | N3: =SUM(F:F) -> 1102 | O3: =L3+M3-N3 -> 506
A4: 管制級別 | B4: 四 | E4: 製造廠名稱 | H4: 美商惠氏藥廠(亞洲)(股)公司
A5: 藥品許可證字號 | C5: 衛署藥輸字第018741號 | H5: 最小單位 | I5: 粒
A6: 日 期 | B6: 收支原因 | C6: 收入數量 | D6: 收入藥品批號 | F6: 支出數量 | H6: 結存數量 | I6: 備 註
A7: 115/01/01 | B7: 上期結存 | C7: 608 | H7: 608 | I7: BPP112000001 | Q7: 嘉鏵 (CDP100000003)
A8: 115/01/05 | B8: 調劑 | F8: 20 | H8: =H7-F8 -> 588 | Q8: 江鎰 (QDA10600000101)
A9: 115/01/07 | B9: 調劑 | F9: 30 | H9: =H8-F9 -> 558
A10: 115/01/09 | B10: 調劑 | F10: 84 | H10: =H9-F10 -> 474
A11: 115/01/24 | B11: 調劑 | F11: 3 | H11: =H10-F11 -> 471
A12: 115/02/01 | B12: 調劑 | F12: 30 | H12: =H11-F12 -> 441
A13: 115/02/02 | B13: 調劑 | F13: 20 | H13: =H12-F13 -> 421
A14: 115/02/05 | B14: 調劑 | F14: 84 | H14: =H13-F14 -> 337
A15: 115/02/21 | B15: 調劑 | F15: 56 | H15: =H14-F15 -> 281
A16: 115/02/28 | B16: 調劑 | F16: 28 | H16: =H15-F16 -> 253
A17: 115/03/02 | B17: 調劑 | F17: 20 | H17: =H16-F17 -> 233
A18: 115/03/03 | B18: 購買 | C18: 1000 | D18: 1256S | H18: 1233 | I18: 久裕
A19: 115/03/05 | B19: 調劑 | F19: 37 | H19: =H18-F19 -> 1196
A20: 115/03/14 | B20: 調劑 | F20: 30 | H20: =H19-F20 -> 1166
A21: 115/03/17 | B21: 調劑 | F21: 14 | H21: =H20-F21 -> 1152
A22: 115/03/18 | B22: 調劑 | F22: 84 | H22: =H21-F22 -> 1068
A23: 115/03/21 | B23: 調劑 | F23: 56 | H23: =H22-F23 -> 1012
A24: 115/03/30 | B24: 調劑 | F24: 20 | H24: =H23-F24 -> 992
A25: 115/04/13 | B25: 調劑 | F25: 7 | H25: =H24-F25 -> 985
A26: 115/04/15 | B26: 調劑 | F26: 84 | H26: =H25-F26 -> 901
A27: 115/04/25 | B27: 調劑 | F27: 28 | H27: =H26-F27 -> 873
A28: 115/04/27 | B28: 調劑 | F28: 3 | H28: =H27-F28 -> 870
A29: 115/05/09 | B29: 調劑 | F29: 3 | H29: =H28-F29 -> 867
A30: 115/05/15 | B30: 調劑 | F30: 56 | H30: =H29-F30 -> 811
... A43: 115/07/23 | B43: 調劑 | F43: 5 | H43: =H42-F43 -> 506

Sheet 3
A1: 【 醫療機構、藥局 】(第 四 級管制藥品) | J1: 天義ADP08900008103 | K1: 調劑 | L1: 購買
A2: 藥代：ERA/ERA2 | B2: 管 制 藥 品 收 支 結 存 簿 冊 | J2: 名稱 | K2: 字號 | L2: 上期結存 | M2: 收入 | N2: 支出 | O2: 結存
A3: 藥品名稱 | B3: ERA 0.25mg | E3: 管制藥品成分及含量 | H3: Fludiazepam 0.25mg | L3: 8 | N3: =SUM(F:F) -> 0 | O3: =L3+M3-N3 -> 8
A4: 管制級別 | B4: 四 | E4: 製造廠名稱 | H4: 台灣東洋藥品工業(股)公司
A5: 藥品許可證字號 | C5: 衛署藥製字第037577號 | H5: 最小單位 | I5: 粒
A6: 日 期 | B6: 收支原因 | C6: 收入數量 | D6: 收入藥品批號 | F6: 支出數量 | H6: 結存數量 | I6: 備 註
A7: 115/01/01 | B7: 上期結存 | C7: 0 | H7: 0 | I7: BPP112000001

Sheet 4
A1: 【 醫療機構、藥局 】(第 四 級管制藥品)
A2: 藥代：ESTA,ELA | B2: 管 制 藥 品 收 支 結 存 簿 冊 | J2: 名稱 | K2: 字號 | L2: 上期結存 | M2: 收入 | N2: 支出 | O2: 結存
A3: 藥品名稱 | B3: ELAM 2mg | E3: 管制藥品成分及含量 | H3: Estazolam 2mg | J3: =B3 -> ELAM 2mg | K3: 43860 | L3: =H7 -> 1038.5 | M3: =SUM(C$8:C$1048576) -> 0 | N3: =SUM(F:F) -> 600 | O3: =L3+M3-N3 -> 438.5
A4: 管制級別 | B4: 四 | E4: 製造廠名稱 | H4: 永勝藥品工業(股)公司
A5: 藥品許可證字號 | C5: 衛署藥製字第043860號 | H5: 最小單位 | I5: 粒
A6: 日 期 | B6: 收支原因 | C6: 收入數量 | D6: 收入藥品批號 | F6: 支出數量 | H6: 結存數量 | I6: 備 註
A7: 115/01/01 | B7: 上期結存 | C7: 1038.5 | H7: 1038.5 | I7: BPP112000001
A8: 115/01/07 | B8: 調劑 | F8: 30 | H8: =H7-F8 -> 1008.5
A9: 115/01/07 | B9: 調劑 | F9: 30 | H9: =H8-F9 -> 978.5
A10: 115/01/16 | B10: 調劑 | F10: 30 | H10: =H9-F10 -> 948.5
A11: 115/02/03 | B11: 調劑 | F11: 30 | H11: =H10-F11 -> 918.5
A12: 115/02/12 | B12: 調劑 | F12: 14 | H12: =H11-F12 -> 904.5
A13: 115/02/15 | B13: 調劑 | F13: 7 | H13: =H12-F13 -> 897.5
A14: 115/02/26 | B14: 調劑 | F14: 3 | H14: =H13-F14 -> 894.5
A15: 115/03/02 | B15: 調劑 | F15: 30 | H15: =H14-F15 -> 864.5
A16: 115/03/09 | B16: 調劑 | F16: 60 | H16: =H15-F16 -> 804.5
A17: 115/03/20 | B17: 調劑 | F17: 14 | H17: =H16-F17 -> 790.5
A18: 115/03/31 | B18: 調劑 | F18: 30 | H18: =H17-F18 -> 760.5
A19: 115/04/01 | B19: 調劑 | F19: 30 | H19: =H18-F19 -> 730.5
... A29: 115/07/14 | B29: 調劑 | F29: 7 | H29: =H28-F29 -> 438.5

Sheet 5
A1: 【 醫療機構、藥局 】(第 三 級管制藥品)
A2: 藥代：HALC | B2: 管 制 藥 品 收 支 結 存 簿 冊 | J2: 名稱 | K2: 字號 | L2: 上期結存 | M2: 收入 | N2: 支出 | O2: 結存
A3: 藥品名稱 | B3: Halcion 0.25mg | E3: 管制藥品成分及含量 | H3: Triazolam 0.25mg | J3: =B3 -> Halcion 0.25mg | K3: 21726 | L3: =H7 -> 136.5 | M3: =SUM(C$8:C$1048576) -> 300 | N3: =SUM(F:F) -> 312 | O3: =L3+M3-N3 -> 124.5
A4: 管制級別 | B4: 三 | E4: 製造廠名稱 | H4: 輝瑞大藥廠(股)公司
A5: 藥品許可證字號 | C5: 衛署藥輸字第021726號 | H5: 最小單位 | I5: 粒
A6: 日 期 | B6: 收支原因 | C6: 收入數量 | D6: 收入藥品批號 | F6: 支出數量 | H6: 結存數量 | I6: 備 註
A7: 115/01/01 | B7: 上期結存 | C7: 136.5 | H7: 136.5 | I7: BPP112000001
A8: 115/01/05 | B8: 調劑 | F8: 30 | H8: =H7-F8 -> 106.5 | I8: 施秀媚 (C200972006)
A9: 115/01/08 | B9: 調劑 | F9: 42 | H9: =H8-F9 -> 64.5 | I9: 邵素雲(Q202326156)
A10: 115/02/08 | B10: 調劑 | F10: 42 | H10: =H9-F10 -> 22.5 | I10: 邵素雲(Q202326156)
A11: 115/02/10 | B11: 購買 | C11: 100 | D11: MR8665 | H11: 122.5 | I11: 嘉鏵
A12: 115/04/09 | B12: 調劑 | F12: 42 | H12: =H11-F12 -> 80.5 | I12: 邵素雲(Q202326156)
A13: 115/04/29 | B13: 調劑 | F13: 42 | H13: =H12-F13 -> 38.5 | I13: 黃惠美(J220676001)
A14: 115/04/30 | B14: 購買 | C14: 100 | D14: MR8657 | H14: 138.5 | I14: 邵素雲(Q202326156)
A15: 115/06/25 | B15: 調劑 | F15: 72 | H15: =H14-F15 -> 66.5 | I15: 施秀媚 (C200972006)
A16: 115/07/22 | B16: 調劑 | F16: 42 | H16: =H15-F16 -> 24.5 | I16: 邵素雲(Q202326156)
A17: 115/07/23 | B17: 購買 | C17: 100 | D17: NK4188 | H17: 124.5 | I17: 嘉鏵
I19: 邵素雲(Q202326156)
I20: 嘉鏵

Sheet 6
A1: 【 醫療機構、藥局 】(第 四 級管制藥品)
A2: 藥代：ONSL | B2: 管 制 藥 品 收 支 結 存 簿 冊 | J2: 名稱 | K2: 字號 | L2: 上期結存 | M2: 收入 | N2: 支出 | O2: 結存
A3: 藥品名稱 | B3: Onsleep 10mg | E3: 管制藥品成分及含量 | H3: Zaleplon 10mg | J3: =B3 -> Onsleep 10mg | K3: 49166 | L3: 0 | M3: =SUM(C:C) -> 0 | N3: =SUM(F:F) -> 0 | O3: =L3+M3-N3 -> 0
A4: 管制級別 | B4: 四 | E4: 製造廠名稱 | H4: 生達化學製藥(股)公司
A5: 藥品許可證字號 | C5: 衛署藥製字第049166號 | H5: 最小單位 | I5: 粒
A6: 日 期 | B6: 收支原因 | C6: 收入數量 | D6: 收入藥品批號 | F6: 支出數量 | H6: 結存數量 | I6: 備 註
A7: 115/01/01 | B7: 上期結存 | C7: 0 | H7: 0

Sheet 7
A1: 【 醫療機構、藥局 】(第 四 級管制藥品)
A2: 藥代：RIVT/CLO1 | B2: 管 制 藥 品 收 支 結 存 簿 冊 | J2: 名稱 | K2: 字號 | L2: 上期結存 | M2: 收入 | N2: 支出 | O2: 結存
A3: 藥品名稱 | B3: Clonazepam 0.5mg | E3: 管制藥品成分及含量 | H3: Clonazepam 0.5mg | J3: =B3 -> Clonazepam 0.5mg | K3: 45342 | L3: =H7 -> 345.5 | M3: =SUM(C$8:C$1048576) -> 300 | N3: =SUM(F:F) -> 501 | O3: =L3+M3-N3 -> 144.5
A4: 管制級別 | B4: 四 | E4: 製造廠名稱 | H4: 榮民製藥(股)公司
A5: 藥品許可證字號 | C5: 衛署藥製字第045342號 | H5: 最小單位 | I5: 粒
A6: 日 期 | B6: 收支原因 | C6: 收入數量 | D6: 收入藥品批號 | F6: 支出數量 | H6: 結存數量 | I6: 備 註
A7: 115/01/01 | B7: 上期結存 | C7: 345.5 | H7: =C7 -> 345.5 | I7: BPP112000001
A8: 115/01/09 | B8: 調劑 | F8: 6 | H8: =H7-F8 -> 339.5
A9: 115/01/13 | B9: 調劑 | F9: 56 | H9: =H8-F9 -> 283.5
A10: 115/01/17 | B10: 調劑 | F10: 6 | H10: =H9-F10 -> 277.5
A11: 115/01/27 | B11: 調劑 | F11: 6 | H11: =H10-F11 -> 271.5 | I11: 嘉鏵
A12: 115/02/07 | B12: 調劑 | F12: 6 | H12: =H11-F12 -> 265.5
A13: 115/02/13 | B13: 調劑 | F13: 34 | H13: =H12-F13 -> 231.5 | I13: 嘉鏵CDP100000003
A14: 115/02/21 | B14: 調劑 | F14: 6 | H14: =H13-F14 -> 225.5
A15: 115/03/03 | B15: 調劑 | F15: 6 | H15: =H14-F15 -> 219.5
A16: 115/03/11 | B16: 調劑 | F16: 56 | H16: =H15-F16 -> 163.5
A17: 115/03/14 | B17: 調劑 | F17: 6 | H17: =H16-F17 -> 157.5
A18: 115/03/24 | B18: 調劑 | F18: 6 | H18: =H17-F18 -> 151.5
A19: 115/04/02 | B19: 調劑 | F19: 6 | H19: =H18-F19 -> 145.5
A20: 115/04/09 | B20: 調劑 | F20: 56 | H20: =H19-F20 -> 89.5
A21: 115/04/10 | B21: 調劑 | F21: 6 | H21: =H20-F21 -> 83.5 | I21: 嘉鏵
A22: 115/04/15 | B22: 調劑 | F22: 28 | H22: =H21-F22 -> 55.5
A23: 115/04/18 | B23: 調劑 | F23: 6 | H23: =H22-F23 -> 49.5
A24: 115/04/27 | B24: 購買 | C24: 200 | D24: 2K816 | H24: 249.5 | I24: 嘉鏵
A25: 115/04/28 | B25: 調劑 | F25: 6 | H25: =H24-F25 -> 243.5
A26: 115/05/04 | B26: 調劑 | F26: 5 | H26: =H25-F26 -> 238.5
A27: 115/05/07 | B27: 調劑 | F27: 6 | H27: =H26-F27 -> 232.5
A28: 115/05/12 | B28: 調劑 | F28: 28 | H28: =H27-F28 -> 204.5 | I28: 嘉鏵
A29: 115/05/16 | B29: 調劑 | F29: 6 | H29: =H28-F29 -> 198.5
A30: 115/05/26 | B30: 調劑 | F30: 6 | H30: =H29-F30 -> 192.5
A31: 115/06/01 | B31: 調劑 | F31: 56 | H31: =H30-F31 -> 136.5
A32: 115/06/04 | B32: 調劑 | F32: 6 | H32: =H31-F32 -> 130.5
A33: 115/06/13 | B33: 調劑 | F33: 6 | H33: =H32-F33 -> 124.5
A34: 115/06/24 | B34: 調劑 | F34: 6 | H34: =H33-F34 -> 118.5
A35: 115/06/27 | B35: 調劑 | F35: 56 | H35: =H34-F35 -> 62.5 | L35: CLONO
A36: 115/06/30 | B36: 購買 | C36: 100 | D36: 2KC56 | H36: 162.5 | I36: 嘉鏵CDP100000003
A37: 115/07/03 | B37: 調劑 | F37: 6 | H37: =H36-F37 -> 156.5
A38: 115/07/13 | B38: 調劑 | F38: 6 | H38: =H37-F38 -> 150.5
A39: 115/07/22 | B39: 調劑 | F39: 6 | H39: =H38-F39 -> 144.5

Sheet 8
A1: 【 醫療機構、藥局 】(第 四 級管制藥品) | J1: 惠勝MDP09300000203 | K1: 調劑 | L1: 購買
A2: 藥代：SULN | B2: 管 制 藥 品 收 支 結 存 簿 冊 | J2: 名稱 | K2: 字號 | L2: 上期結存 | M2: 收入 | N2: 支出 | O2: 結存
A3: 藥品名稱 | B3: SULNINE 10mg | E3: 管制藥品成分及含量 | H3: Oxazolam 10mg | J3: =B3 -> SULNINE 10mg | K3: 035256 | L3: =H7 -> 415 | M3: =SUM(C$8:C$1048576) -> 3000 | N3: =SUM(F:F) -> 2213 | O3: =L3+M3-N3 -> 1202
A4: 管制級別 | B4: 四 | E4: 製造廠名稱 | H4: 永勝藥品工業(股)公司
A5: 藥品許可證字號 | C5: 衛署藥製字第035256號 | H5: 最小單位 | I5: 粒
A6: 日 期 | B6: 收支原因 | C6: 收入數量 | D6: 收入藥品批號 | F6: 支出數量 | H6: 結存數量 | I6: 備 註
A7: 115/01/01 | B7: 上期結存 | C7: 415 | H7: 415 | I7: BPP112000001
A8: 115/01/01 | B8: 調劑 | F8: 7 | H8: =H7-F8 -> 408
A9: 115/01/05 | B9: 調劑 | F9: 28 | H9: =H8-F9 -> 380
A10: 115/01/07 | B10: 調劑 | F10: 29 | H10: =H9-F10 -> 351
A11: 115/01/09 | B11: 調劑 | F11: 18 | H11: =H10-F11 -> 333
A12: 115/01/12 | B12: 調劑 | F12: 6 | H12: =H11-F12 -> 327
A13: 115/01/13 | B13: 調劑 | F13: 27 | H13: =H12-F13 -> 300
A14: 115/01/15 | B14: 調劑 | F14: 12 | H14: =H13-F14 -> 288
A15: 115/01/16 | B15: 調劑 | F15: 10 | H15: =H14-F15 -> 278
A16: 115/01/17 | B16: 調劑 | F16: 18 | H16: =H15-F16 -> 260
A17: 115/01/19 | B17: 調劑 | F17: 9 | H17: =H16-F17 -> 251
A18: 115/01/21 | B18: 購買 | C18: 1000 | D18: R1100105 | H18: 1251 | I18: 惠勝
A19: 115/01/21 | B19: 調劑 | F19: 14 | H19: =H18-F19 -> 1237
A20: 115/01/22 | B20: 調劑 | F20: 6 | H20: =H19-F20 -> 1231
A21: 115/01/24 | B21: 調劑 | F21: 6 | H21: =H20-F21 -> 1225
A22: 115/01/26 | B22: 調劑 | F22: 33 | H22: =H21-F22 -> 1192
A23: 115/01/27 | B23: 調劑 | F23: 18 | H23: =H22-F23 -> 1174
A24: 115/01/29 | B24: 調劑 | F24: 36 | H24: =H23-F24 -> 1138
A25: 115/01/30 | B25: 調劑 | F25: 30 | H25: =H24-F25 -> 1108
A26: 115/02/01 | B26: 調劑 | F26: 6 | H26: =H25-F26 -> 1102
A27: 115/02/02 | B27: 調劑 | F27: 34 | H27: =H26-F27 -> 1068
A28: 115/02/03 | B28: 調劑 | F28: 21 | H28: =H27-F28 -> 1047
A29: 115/02/04 | B29: 調劑 | F29: 22 | H29: =H28-F29 -> 1025
A30: 115/02/05 | B30: 調劑 | F30: 27 | H30: =H29-F30 -> 998
... A49: 115/03/17 | B49: 調劑 | F49: 21 | H49: =H48-F49 -> 580
A50: 115/03/18 | B50: 購買 | C50: 1000 | D50: R1100105 | H50: 1580 | I50: 惠勝MDP09300000203
A51: 115/03/20 | B51: 調劑 | F51: 21 | H51: =H50-F51 -> 1559
A52: 115/03/24 | B52: 調劑 | F52: 24 | H52: =H51-F52 -> 1535
A53: 115/03/25 | B53: 調劑 | F53: 6 | H53: =H52-F53 -> 1529
A54: 115/03/27 | B54: 調劑 | F54: 60 | H54: =H53-F54 -> 1469
A55: 115/03/30 | B55: 調劑 | F55: 61 | H55: =H54-F55 -> 1408
A56: 115/03/31 | B56: 調劑 | F56: 51 | H56: =H55-F56 -> 1357
A57: 115/04/01 | B57: 調劑 | F57: 5 | H57: =H56-F57 -> 1352
A58: 115/04/02 | B58: 調劑 | F58: 18 | H58: =H57-F58 -> 1334
...

Sheet 9
A1: 【 醫療機構、藥局 】(第 四 級管制藥品) | J1: 永信 | K1: 調劑 | L1: 購買
A2: 藥代：VA2P | B2: 管 制 藥 品 收 支 結 存 簿 冊 | J2: 名稱 | K2: 字號 | L2: 上期結存 | M2: 收入 | N2: 支出 | O2: 結存
A3: 藥品名稱 | B3: Diazepam 2mg | E3: 管制藥品成分及含量 | H3: Diazepam 2mg | J3: =B3 -> Diazepam 2mg | K3: 030507 | L3: =H7 -> 706 | M3: =SUM(C$8:C$1048576) -> 1000 | N3: =SUM(F:F) -> 1390 | O3: =L3+M3-N3 -> 316
A4: 管制級別 | B4: 四 | E4: 製造廠名稱 | H4: 永信藥品工業股份有限公司
A5: 藥品許可證字號 | C5: 衛署藥製字第030507號 | H5: 最小單位 | I5: 粒
A6: 日 期 | B6: 收支原因 | C6: 收入數量 | D6: 收入藥品批號 | F6: 支出數量 | H6: 結存數量 | I6: 備 註
A7: 115/01/01 | B7: 上期結存 | C7: 706 | H7: 706 | I7: BPP112000001
A8: 115/01/02 | B8: 調劑 | F8: 7.5 | H8: =H7-F8 -> 698.5
A9: 115/01/05 | B9: 調劑 | F9: 4.5 | H9: =H8-F9 -> 694
A10: 115/01/06 | B10: 調劑 | F10: 21 | H10: =H9-F10 -> 673
A11: 115/01/07 | B11: 調劑 | F11: 18 | H11: =H10-F11 -> 655
A12: 115/01/08 | B12: 調劑 | F12: 14 | H12: =H11-F12 -> 641
A13: 115/01/09 | B13: 調劑 | F13: 7.5 | H13: =H12-F13 -> 633.5
A14: 115/01/12 | B14: 調劑 | F14: 4.5 | H14: =H13-F14 -> 629
A15: 115/01/13 | B15: 調劑 | F15: 21 | H15: =H14-F15 -> 608
A16: 115/01/14 | B16: 調劑 | F16: 3 | H16: =H15-F16 -> 605
A17: 115/01/15 | B17: 調劑 | F17: 9 | H17: =H16-F17 -> 596
A18: 115/01/16 | B18: 調劑 | F18: 18 | H18: =H17-F18 -> 578
A19: 115/01/19 | B19: 調劑 | F19: 14 | H19: =H18-F19 -> 564
... A51: 115/03/23 | B51: 調劑 | F51: 32 | H51: =H50-F51 -> 135.5
A52: 115/03/24 | B52: 購買 | C52: 1000 | D52: BRT2 T003 | H52: 1135.5 | I52: 永信
A53: 115/03/24 | B53: 調劑 | F53: 9 | H53: =H52-F53 -> 1126.5
A54: 115/03/26 | B54: 調劑 | F54: 4.5 | H54: =H53-F54 -> 1122
A55: 115/03/28 | B55: 調劑 | F55: 21 | H55: =H54-F55 -> 1101
A56: 115/03/29 | B56: 調劑 | F56: 9 | H56: =H55-F56 -> 1092
A57: 115/03/30 | B57: 調劑 | F57: 28 | H57: =H56-F57 -> 1064
A58: 115/3/31 | B58: 調劑 | F58: 4.5 | H58: =H57-F58 -> 1059.5
A59: 115/04/02 | B59: 調劑 | F59: 4.5 | H59: =H58-F59 -> 1055
A60: 115/04/04 | B60: 調劑 | F60: 21 | H60: =H59-F60 -> 1034
A61: 115/04/08 | B61: 調劑 | F61: 6 | H61: =H60-F61 -> 1028
A62: 115/04/11 | B62: 調劑 | F62: 19.5 | H62: =H61-F62 -> 1008.5
A63: 115/04/12 | B63: 調劑 | F63: 5 | H63: =H62-F63 -> 1003.5
A64: 115/04/15 | B64: 調劑 | F64: 4.5 | H64: =H63-F64 -> 999
A65: 115/04/16 | B65: 調劑 | F65: 14 | H65: =H64-F65 -> 985
A66: 115/04/17 | B66: 調劑 | F66: 25.5 | H66: =H65-F66 -> 959.5 | I66: 永信HFP10100000101
A67: 115/04/21 | B67: 調劑 | F67: 4.5 | H67: =H66-F67 -> 955
A68: 115/04/22 | B68: 調劑 | F68: 5 | H68: =H67-F68 -> 950
A69: 115/04/23 | B69: 調劑 | F69: 4.5 | H69: =H68-F69 -> 945.5
A70: 115/04/24 | B70: 調劑 | F70: 9 | H70: =H69-F70 -> 936.5
A71: 115/04/25 | B71: 調劑 | F71: 21 | H71: =H70-F71 -> 915.5
...

Sheet 11
A1: 【 醫療機構、藥局 】(第 四 級管制藥品)
A2: 藥代：ZOL2 | B2: 管 制 藥 品 收 支 結 存 簿 冊 | J2: 名稱 | K2: 字號 | L2: 上期結存 | M2: 收入 | N2: 支出 | O2: 結存
A3: 藥品名稱 | B3: Zolpidem 10mg | E3: 管制藥品成分及含量 | H3: Zolpidem 10mg | J3: =B3 -> Zolpidem 10mg | K3: 046255 | L3: 0 | M3: =SUM(C:C) -> 0 | N3: =SUM(F:F) -> 0 | O3: =L3+M3-N3 -> 0
A4: 管制級別 | B4: 四 | E4: 製造廠名稱 | H4: 中國化學製藥股份有限公司
A5: 藥品許可證字號 | C5: 衛署藥製字第046255號 | H5: 最小單位 | I5: 粒
A6: 日 期 | B6: 收支原因 | C6: 收入數量 | D6: 收入藥品批號 | F6: 支出數量 | H6: 結存數量 | I6: 備 註
A7: 115/01/01 | B7: 上期結存 | C7: 0 | H7: 0

Sheet 10
A1: 【 醫療機構、藥局 】(第 四 級管制藥品)
A2: 藥代：ZODE/ZOD1 | B2: 管 制 藥 品 收 支 結 存 簿 冊 | J2: 名稱 | K2: 字號 | L2: 上期結存 | M2: 收入 | N2: 支出 | O2: 結存
A3: 藥品名稱 | B3: Zodenox 10mg | E3: 管制藥品成分及含量 | H3: Zolpidem 10mg | J3: =B3 -> Zodenox 10mg | K3: 049217 | L3: =H7 -> 32 | M3: =SUM(C$8:C$1048576) -> 360 | N3: =SUM(F:F) -> 252 | O3: =L3+M3-N3 -> 140
A4: 管制級別 | B4: 四 | E4: 製造廠名稱 | H4: 永信藥品工業股份有限公司
A5: 藥品許可證字號 | C5: 衛署藥製字第049217號 | H5: 最小單位 | I5: 粒
A6: 日 期 | B6: 收支原因 | C6: 收入數量 | D6: 收入藥品批號 | F6: 支出數量 | H6: 結存數量 | I6: 備 註
A7: 115/01/01 | B7: 上期結存 | C7: 32 | H7: 32 | I7: 嘉鏵
A8: 115/01/09 | B8: 調劑 | F8: 28 | H8: =H7-F8 -> 4
A9: 115/02/26 | B9: 購買 | C9: 100 | D9: ZOTT003 | H9: 104 | I9: 江鎰
A10: 115/02/28 | B10: 調劑 | F10: 28 | H10: =H9-F10 -> 76
A11: 115/03/24 | B11: 調劑 | F11: 28 | H11: =H10-F11 -> 48
A12: 115/04/04 | B12: 調劑 | F12: 28 | H12: =H11-F12 -> 20
A13: 115/04/10 | B13: 購買 | C13: 200 | D13: ZOTT003 | H13: 220 | I13: 嘉鏵CDP100000003
A14: 115/04/24 | B14: 調劑 | F14: 28 | H14: =H13-F14 -> 192
A15: 115/04/27 | B15: 購買 | C15: 60 | D15: ZOTT004 | H15: 252 | I15: 嘉鏵CDP100000003
A16: 115/05/14 | B16: 調劑 | F16: 28 | H16: =H15-F16 -> 224
A17: 115/06/18 | B17: 調劑 | F17: 28 | H17: =H16-F17 -> 196
A18: 115/06/19 | B18: 調劑 | F18: 28 | H18: =H17-F18 -> 168
A19: 115/07/18 | B19: 調劑 | F19: 28 | H19: =H18-F19 -> 140

Sheet 12
A1: 【 醫療機構、藥局 】(第 四 級管制藥品)
A2: 藥代：ZOLA/ZOL5 | B2: 管 制 藥 品 收 支 結 存 簿 冊 | J2: 名稱 | K2: 字號 | L2: 上期結存 | M2: 收入 | N2: 支出 | O2: 結存
A3: 藥品名稱 | B3: Zolpidem 10mg | E3: 管制藥品成分及含量 | H3: Zolpidem 10mg | J3: =B3 -> Zolpidem 10mg | K3: 57306 | L3: =H7 -> 2233 | M3: =SUM(C$8:C$1048576) -> 3000 | N3: =SUM(F:F) -> 3043 | O3: =L3+M3-N3 -> 2190
A4: 管制級別 | B4: 四 | E4: 製造廠名稱 | H4: 中國化學製藥股份有限公司
A5: 藥品許可證字號 | C5: 衛署藥製字第057306號 | H5: 最小單位 | I5: 粒
A6: 日 期 | B6: 收支原因 | C6: 收入數量 | D6: 收入藥品批號 | F6: 支出數量 | H6: 結存數量 | I6: 備 註
A7: 115/01/01 | B7: 上期結存 | C7: 2233 | H7: 2233 | I7: 維元社區藥局 (BPP112000001)
A8: 115/01/02 | B8: 調劑 | F8: 28 | H8: =H7-F8 -> 2205
A9: 115/01/03 | B9: 調劑 | F9: 60 | H9: =H8-F9 -> 2145
A10: 115/01/05 | B10: 調劑 | F10: 90 | H10: =H9-F10 -> 2055
A11: 115/01/07 | B11: 調劑 | F11: 30 | H11: =H10-F11 -> 2025
A12: 115/01/08 | B12: 調劑 | F12: 28 | H12: =H11-F12 -> 1997
A13: 115/01/09 | B13: 調劑 | F13: 60 | H13: =H12-F13 -> 1937
A14: 115/01/12 | B14: 調劑 | F14: 15 | H14: =H13-F14 -> 1922
A15: 115/01/14 | B15: 調劑 | F15: 14 | H15: =H14-F15 -> 1908
A16: 115/01/23 | B16: 調劑 | F16: 28 | H16: =H15-F16 -> 1880
A17: 115/01/27 | B17: 調劑 | F17: 30 | H17: =H16-F17 -> 1850
A18: 115/01/28 | B18: 調劑 | F18: 60 | H18: =H17-F18 -> 1790
A19: 115/02/02 | B19: 調劑 | F19: 90 | H19: =H18-F19 -> 1700
A20: 115/02/03 | B20: 購買 | C20: 1000 | D20: E2560225 | H20: 2700 | I20: 中化
A21: 115/02/03 | B21: 調劑 | F21: 7 | H21: =H20-F21 -> 2693
A22: 115/02/04 | B22: 調劑 | F22: 30 | H22: =H21-F22 -> 2663 | I22: 中化ADP09200001603
A23: 115/02/05 | B23: 調劑 | F23: 30 | H23: =H22-F23 -> 2633
A24: 115/02/06 | B24: 調劑 | F24: 28 | H24: =H23-F24 -> 2605
A25: 115/02/09 | B25: 調劑 | F25: 15 | H25: =H24-F25 -> 2590
A26: 115/02/11 | B26: 調劑 | F26: 86 | H26: =H25-F26 -> 2504
A27: 115/02/12 | B27: 調劑 | F27: 30 | H27: =H26-F27 -> 2474
A28: 115/02/13 | B28: 調劑 | F28: 28 | H28: =H27-F28 -> 2446
A29: 115/02/22 | B29: 調劑 | F29: 30 | H29: =H28-F29 -> 2416
A30: 115/02/25 | B30: 調劑 | F30: 60 | H30: =H29-F30 -> 2356
A31: 115/02/26 | B31: 調劑 | F31: 60 | H31: =H30-F31 -> 2296
A32: 115/02/28 | B32: 調劑 | F32: 30 | H32: =H31-F32 -> 2266
A33: 115/03/03 | B33: 調劑 | F33: 30 | H33: =H32-F33 -> 2236
A34: 115/03/04 | B34: 調劑 | F34: 88 | H34: =H33-F34 -> 2148
... A63: 115/05/20 | B63: 調劑 | F63: 14 | H63: =H62-F63 -> 1108
A64: 115/05/22 | B64: 調劑 | F64: 30 | H64: =H63-F64 -> 1078 | I64: 中化
A65: 115/05/27 | B65: 調劑 | F65: 90 | H65: =H64-F65 -> 988
A66: 115/05/29 | B66: 調劑 | F66: 30 | H66: =H65-F66 -> 958
A67: 115/05/30 | B67: 調劑 | F67: 60 | H67: =H66-F67 -> 898
A68: 115/06/02 | B68: 調劑 | F68: 28 | H68: =H67-F68 -> 870
...

Sheet 13
A1: 【 醫療機構、藥局 】(第 四 級管制藥品)
A2: 藥代：DIAL/DIA1 | B2: 管 制 藥 品 收 支 結 存 簿 冊 | J2: 名稱 | K2: 字號 | L2: 上期結存 | M2: 收入 | N2: 支出 | O2: 結存
A3: 藥品名稱 | B3: Diapin 2mg | E3: 管制藥品成分及含量 | H3: Diazepam 2mg | J3: =B3 -> Diapin 2mg | K3: 000059 | L3: =H7 -> 76 | M3: =SUM(C$8:C$1048576) -> 0 | N3: =SUM(F:F) -> 28 | O3: =L3+M3-N3 -> 48
A4: 管制級別 | B4: 四 | E4: 製造廠名稱 | H4: 韋淳貿易股份有限公司 | O4: =N3 -> 28
A5: 藥品許可證字號 | C5: 衛署藥製字第000059號 | H5: 最小單位 | I5: 粒
A6: 日 期 | B6: 收支原因 | C6: 收入數量 | D6: 收入藥品批號 | F6: 支出數量 | H6: 結存數量 | I6: 備 註
A7: 115/01/01 | B7: 上期結存 | C7: 76 | H7: 76 | I7: 維元社區藥局 (BPP112000001)
A8: 115/03/02 | B8: 調劑 | F8: 28 | H8: =H7-F8 -> 48

Sheet 14
A1: 【 醫療機構、藥局 】(第 四 級管制藥品) | J1: 嘉鏵(CDP100000003) | K1: 江鎰(QDA10600000101) | L1: 調劑 | M1: 購買
A2: 藥代：ESZO/ ESZ2/ESZ | B2: 管 制 藥 品 收 支 結 存 簿 冊 | J2: 名稱 | K2: 字號 | L2: 上期結存 | M2: 收入 | N2: 支出 | O2: 結存
A3: 藥品名稱 | B3: Eszo 2mg | E3: 管制藥品成分及含量 | H3: Estazolam 2mg | J3: =B3 -> Eszo 2mg | K3: 042646 | L3: =H7 -> 482.5 | M3: =SUM(C$8:C$1048576) -> 1000 | N3: =SUM(F:F) -> 1164 | O3: =L3+M3-N3 -> 318.5
A4: 管制級別 | B4: 四 | E4: 製造廠名稱 | H4: 信東生技股份有限公司
A5: 藥品許可證字號 | C5: 衛署藥製字第042646號 | H5: 最小單位 | I5: 粒
A6: 日 期 | B6: 收支原因 | C6: 收入數量 | D6: 收入藥品批號 | F6: 支出數量 | H6: 結存數量 | I6: 備 註
A7: 115/01/01 | B7: 上期結存 | C7: 482.5 | H7: 482.5 | I7: 維元社區藥局 (BPP112000001)
A8: 115/01/01 | B8: 調劑 | F8: 28 | H8: =H7-F8 -> 454.5
A9: 115/01/05 | B9: 調劑 | F9: 14 | H9: =H8-F9 -> 440.5
A10: 115/01/07 | B10: 調劑 | F10: 28 | H10: =H9-F10 -> 412.5
A11: 115/01/08 | B11: 調劑 | F11: 60 | H11: =H10-F11 -> 352.5
A12: 115/01/12 | B12: 調劑 | F12: 42 | H12: =H11-F12 -> 310.5
A13: 115/01/14 | B13: 調劑 | F13: 28 | H13: =H12-F13 -> 282.5
A14: 115/01/15 | B14: 調劑 | F14: 14 | H14: =H13-F14 -> 268.5
A15: 115/01/22 | B15: 調劑 | F15: 28 | H15: =H14-F15 -> 240.5
A16: 115/01/27 | B16: 調劑 | F16: 30 | H16: =H15-F16 -> 210.5 | I16: 嘉鏵CDP100000003
A17: 115/02/07 | B17: 調劑 | F17: 30 | H17: =H16-F17 -> 180.5
A18: 115/02/11 | B18: 調劑 | F18: 28 | H18: =H17-F18 -> 152.5
A19: 115/02/12 | B19: 調劑 | F19: 14 | H19: =H18-F19 -> 138.5
A20: 115/02/13 | B20: 購買 | C20: 400 | D20: 2540301 | H20: 538.5 | I20: 嘉鏵CDP100000003
A21: 115/02/24 | B21: 調劑 | F21: 28 | H21: =H20-F21 -> 510.5
A22: 115/02/25 | B22: 調劑 | F22: 42 | H22: =H21-F22 -> 468.5 | I22: 嘉鏵CDP100000003
A23: 115/02/26 | B23: 調劑 | F23: 79 | H23: =H22-F23 -> 389.5
A24: 115/02/27 | B24: 調劑 | F24: 28 | H24: =H23-F24 -> 361.5
A25: 115/03/04 | B25: 調劑 | F25: 28 | H25: =H24-F25 -> 333.5
A26: 115/03/05 | B26: 調劑 | F26: 7 | H26: =H25-F26 -> 326.5
A27: 115/03/24 | B27: 調劑 | F27: 28 | H27: =H26-F27 -> 298.5
A28: 115/03/25 | B28: 調劑 | F28: 14 | H28: =H27-F28 -> 284.5
A29: 115/03/25 | B29: 購買 | C29: 300 | D29: 2540308 | H29: 584.5 | I29: 嘉鏵CDP100000003
A30: 115/03/29 | B30: 調劑 | F30: 30 | H30: =H29-F30 -> 554.5
A31: 115/03/31 | B31: 調劑 | F31: 28 | H31: =H30-F31 -> 526.5
A32: 115/04/02 | B32: 調劑 | F32: 28 | H32: =H31-F32 -> 498.5
A33: 115/04/10 | B33: 調劑 | F33: 42 | H33: =H32-F33 -> 456.5
A34: 115/04/23 | B34: 調劑 | F34: 14 | H34: =H33-F34 -> 442.5
A35: 115/04/26 | B35: 調劑 | F35: 30 | H35: =H34-F35 -> 412.5
A36: 115/04/28 | B36: 調劑 | F36: 15 | H36: =H35-F36 -> 397.5 | I36: QDA10600000101 江鎰
A37: 115/04/30 | B37: 調劑 | F37: 15 | H37: =H36-F37 -> 382.5
A38: 115/05/16 | B38: 調劑 | F38: 28 | H38: =H37-F38 -> 354.5
A39: 115/05/19 | B39: 調劑 | F39: 56 | H39: =H38-F39 -> 298.5
A40: 115/05/23 | B40: 調劑 | F40: 28 | H40: =H39-F40 -> 270.5
...

Sheet 15
A1: 【 醫療機構、藥局 】(第 四 級管制藥品)
A2: 藥代：FLU2/FLUH | B2: 管 制 藥 品 收 支 結 存 簿 冊 | J2: 名稱 | K2: 字號 | L2: 上期結存 | M2: 收入 | N2: 支出 | O2: 結存
A3: 藥品名稱 | B3: Flupine 0.25mg | E3: 管制藥品成分及含量 | H3: Fludiazepam 0.25mg | J3: =B3 -> Flupine 0.25mg | K3: 041519 | L3: =H7 -> 79 | M3: =SUM(C$8:C$1048576) -> 300 | N3: =SUM(F:F) -> 224 | O3: =L3+M3-N3 -> 155
A4: 管制級別 | B4: 四 | E4: 製造廠名稱 | H4: 強生化學製藥廠股份有限公司
A5: 藥品許可證字號 | C5: 衛署藥製字第041519號 | H5: 最小單位 | I5: 粒
A6: 日 期 | B6: 收支原因 | C6: 收入數量 | D6: 收入藥品批號 | F6: 支出數量 | H6: 結存數量 | I6: 備 註
A7: 115/01/01 | B7: 上期結存 | C7: 79 | H7: 79 | I7: 維元社區藥局 (BPP112000001)
A8: 115/02/01 | B8: 購買 | C8: 300 | D8: BES011 | H8: 379 | I8: 嘉鏵CDP100000003
A9: 115/02/09 | B9: 調劑 | F9: 56 | H9: =H8-F9 -> 323 | I9: 嘉鏵
A10: 115/03/19 | B10: 調劑 | F10: 56 | H10: =H9-F10 -> 267
A11: 115/06/22 | B11: 調劑 | F11: 56 | H11: =H10-F11 -> 211
A12: 115/07/16 | B12: 調劑 | F12: 56 | H12: =H11-F12 -> 155

Sheet 16
A1: 【 醫療機構、藥局 】(第 四 級管制藥品)
A2: 藥代：LEX | B2: 管 制 藥 品 收 支 結 存 簿 冊 | J2: 名稱 | K2: 字號 | L2: 上期結存 | M2: 收入 | N2: 支出 | O2: 結存
A3: 藥品名稱 | B3: Lexotan 3mg | E3: 管制藥品成分及含量 | H3: Bromazepam 3mg | J3: =B3 -> Lexotan 3mg | K3: 004457 | L3: =H7 -> 3 | M3: =SUM(C$8:C$1048576) -> 350 | N3: =SUM(F:F) -> 308 | O3: =L3+M3-N3 -> 45
A4: 管制級別 | B4: 四 | E4: 製造廠名稱 | H4: 羅氏大藥廠股份有限公司
A5: 藥品許可證字號 | C5: 衛署藥輸字第004457號 | H5: 最小單位 | I5: 粒
A6: 日 期 | B6: 收支原因 | C6: 收入數量 | D6: 收入藥品批號 | F6: 支出數量 | H6: 結存數量 | I6: 備 註
A7: 115/01/01 | B7: 上期結存 | C7: 3 | H7: 3 | I7: 維元社區藥局 (BPP112000001)
A8: 115/01/07 | B8: 購買 | C8: 30 | D8: M1764M1 | H8: 33 | I8: 嘉鏵CDP100000003
A9: 115/01/12 | B9: 調劑 | F9: 28 | H9: =H8-F9 -> 5
A10: 115/01/17 | B10: 調劑 | F10: 30 | H10: =H9-F10 -> -25
A11: 115/01/18 | B11: 購買 | C11: 90 | D11: M1764M1 | H11: 65 | I11: 嘉鏵CDP100000003
A12: 115/02/14 | B12: 調劑 | F12: 30 | H12: =H11-F12 -> 35
A13: 115/03/11 | B13: 調劑 | F13: 30 | H13: =H12-F13 -> 5
A14: 115/04/10 | B14: 調劑 | F14: 30 | H14: =H13-F14 -> -25
A15: 115/04/10 | B15: 購買 | C15: 100 | D15: M1783M3 | H15: 75 | I15: 嘉鏵CDP100000003
A16: 115/05/11 | B16: 調劑 | F16: 30 | H16: =H15-F16 -> 45
A17: 115/05/25 | B17: 調劑 | F17: 14 | H17: =H16-F17 -> 31
A18: 115/06/04 | B18: 調劑 | F18: 30 | H18: =H17-F18 -> 1
A19: 115/06/07 | B19: 購買 | C19: 30 | D19: M1783M3 | H19: 31 | I19: 嘉鏵CDP100000003
A20: 115/06/08 | B20: 調劑 | F20: 14 | H20: =H19-F20 -> 17
A21: 115/06/22 | B21: 調劑 | F21: 14 | H21: =H20-F21 -> 3
A22: 115/07/04 | B22: 調劑 | F22: 44 | H22: =H21-F22 -> -41
A23: 115/07/05 | B23: 購買 | C23: 100 | D23: M1791M1 | H23: 59 | I23: 嘉鏵CDP100000003
A24: 115/07/19 | B24: 調劑 | F24: 14 | H24: =H23-F24 -> 45

Sheet 17
A1: 【 醫療機構、藥局 】(第 三 級管制藥品)
A2: 藥代：MOD2 | B2: 管 制 藥 品 收 支 結 存 簿 冊 | J2: 名稱 | K2: 字號 | L2: 上期結存 | M2: 收入 | N2: 支出 | O2: 結存
A3: 藥品名稱 | B3: Modipanol 2mg | E3: 管制藥品成分及含量 | H3: Flunitrazepam 2mg | J3: =B3 -> Modipanol 2mg | K3: 37977 | L3: =H7 -> 20 | M3: =SUM(C$8:C$1048576) -> 150 | N3: =SUM(F:F) -> 84 | O3: =L3+M3-N3 -> 86
A4: 管制級別 | B4: 三 | E4: 製造廠名稱 | H4: 瑞士藥廠股份有限公司
A5: 藥品許可證字號 | C5: 衛署藥製字第037997號 | H5: 最小單位 | I5: 粒
A6: 日 期 | B6: 收支原因 | C6: 收入數量 | D6: 收入藥品批號 | F6: 支出數量 | H6: 結存數量 | I6: 備 註
A7: 115/01/01 | B7: 上期結存 | C7: 20 | H7: 20 | I7: 維元社區藥局 (BPP112000001)
A8: 115/02/24 | B8: 購買 | C8: 30 | D8: MDTB56 | H8: 50 | I8: 嘉鏵
A9: 115/02/25 | B9: 購買 | C9: 30 | D9: MDTB56 | H9: 80 | I9: 嘉鏵
A10: 115/02/28 | B10: 調劑 | F10: 42 | H10: =H9-F10 -> 38
A11: 115/03/13 | B11: 購買 | C11: 10 | D11: MDTB56 | H11: 48 | I11: 嘉鏵
A12: 115/03/21 | B12: 調劑 | F12: 42 | H12: =H11-F12 -> 6 | I12: 吳天龍
A13: 115/07/23 | B13: 購買 | C13: 80 | D13: MDTB60 | H13: 86 | I13: 嘉鏵

Sheet 18
A1: 【 醫療機構、藥局 】(第 四 級管制藥品) | J1: 大昌華嘉(ADP09400000703) | K1: 調劑 | L1: 購買
A2: 藥代：RIV1/RIVI/RIV8 | B2: 管 制 藥 品 收 支 結 存 簿 冊 | J2: 名稱 | K2: 字號 | L2: 上期結存 | M2: 收入 | N2: 支出 | O2: 結存
A3: 藥品名稱 | B3: Rivotril 0.5mg | E3: 管制藥品成分及含量 | H3: Clonazepam 0.5mg | J3: =B3 -> Rivotril 0.5mg | K3: 003077 | L3: =H7 -> 991 | M3: =SUM(C$8:C$1048576) -> 5100 | N3: =SUM(F:F) -> 3391.5 | O3: =L3+M3-N3 -> 2699.5
A4: 管制級別 | B4: 四 | E4: 製造廠名稱 | H4: 羅氏大藥廠有限股份公司
A5: 藥品許可證字號 | C5: 衛署藥輸字第003077號 | H5: 最小單位 | I5: 粒
A6: 日 期 | B6: 收支原因 | C6: 收入數量 | D6: 收入藥品批號 | F6: 支出數量 | H6: 結存數量 | I6: 備 註
A7: 115/01/01 | B7: 上期結存 | C7: 991 | H7: 991 | I7: 維元社區藥局 (BPP112000001)
A8: 115/01/01 | B8: 調劑 | F8: 15 | H8: =H7-F8 -> 976
A9: 115/01/02 | B9: 調劑 | F9: 4 | H9: =H8-F9 -> 972
A10: 115/01/03 | B10: 調劑 | F10: 14 | H10: =H9-F10 -> 958
A11: 115/01/05 | B11: 調劑 | F11: 64.5 | H11: =H10-F11 -> 893.5
A12: 115/01/08 | B12: 調劑 | F12: 15 | H12: =H11-F12 -> 878.5
A13: 115/01/09 | B13: 調劑 | F13: 28 | H13: =H12-F13 -> 850.5
A14: 115/01/13 | B14: 調劑 | F14: 14 | H14: =H13-F14 -> 836.5
A15: 115/01/15 | B15: 調劑 | F15: 1.5 | H15: =H14-F15 -> 835
A16: 115/01/16 | B16: 調劑 | F16: 14 | H16: =H15-F16 -> 821
A17: 115/01/17 | B17: 調劑 | F17: 4.5 | H17: =H16-F17 -> 816.5 | T17: 45292 | U17: 33.5 | V17: 1130101 | W17: RIVI | X17: 33.5 | Z17: =U17-X17 -> 0
A18: 115/01/19 | B18: 調劑 | F18: 46 | H18: =H17-F18 -> 770.5 | T18: 45294 | U18: =60 -> 60 | V18: 1130103 | W18: RIV1 | X18: 60 | Z18: =U18-X18 -> 0
A19: 115/01/20 | B19: 調劑 | F19: 7 | H19: =H18-F19 -> 763.5 | I19: QDA10600000101江鎰 | X19: =28+45 -> 73 | Z19: =U19-X19 -> -73
A20: 115/01/21 | B20: 調劑 | F20: 30 | H20: =H19-F20 -> 733.5 | X20: =56+227 -> 283 | Z20: =U20-X20 -> -283
A21: 115/01/22 | B21: 調劑 | F21: 31.5 | H21: =H20-F21 -> 702 | X21: 7 | Z21: =U21-X21 -> -7
A22: 115/01/23 | B22: 調劑 | F22: 30 | H22: =H21-F22 -> 672 | I22: 大昌 | X22: 56 | Z22: =U22-X22 -> -56
A23: 115/01/26 | B23: 調劑 | F23: 10 | H23: =H22-F23 -> 662 | X23: 21 | Z23: =U23-X23 -> -21
A24: 115/01/29 | B24: 調劑 | F24: 75.5 | H24: =H23-F24 -> 586.5 | X24: 65 | Z24: =U24-X24 -> -65
A25: 115/01/31 | B25: 調劑 | F25: 43.5 | H25: =H24-F25 -> 543 | X25: 60 | Z25: =U25-X25 -> -60
A26: 115/02/01 | B26: 調劑 | F26: 4 | H26: =H25-F26 -> 539 | X26: 3 | Z26: =U26-X26 -> -3
A27: 115/02/02 | B27: 調劑 | F27: 14 | H27: =H26-F27 -> 525 | X27: =28+15.5 -> 43.5 | Z27: =U27-X27 -> -43.5
A28: 115/02/03 | B28: 調劑 | F28: 4.5 | H28: =H27-F28 -> 520.5 | X28: 8.5 | Z28: =U28-X28 -> -8.5
A29: 115/02/04 | B29: 調劑 | F29: 28 | H29: =H28-F29 -> 492.5 | X29: 1.5 | Z29: =U29-X29 -> -1.5
A30: 115/02/05 | B30: 調劑 | F30: 43 | H30: =H29-F30 -> 449.5 | X30: 1.5 | Z30: =U30-X30 -> -1.5
A31: 115/02/06 | B31: 購買 | C31: 600 | D31: E3907E1 | H31: 1049.5 | I31: 江鎰 | X31: 32.5 | Z31: =U31-X31 -> -32.5
A32: 115/02/07 | B32: 調劑 | F32: 5 | H32: =H31-F32 -> 1044.5 | X32: 5 | Z32: =U32-X32 -> -5
A33: 115/02/10 | B33: 調劑 | F33: 87 | H33: =H32-F33 -> 957.5 | X33: 1.5 | Z33: =U33-X33 -> -1.5
A34: 115/02/11 | B34: 調劑 | F34: 28 | H34: =H33-F34 -> 929.5 | X34: 32.5 | Z34: =U34-X34 -> -32.5
A35: 115/02/13 | B35: 調劑 | F35: 30 | H35: =H34-F35 -> 899.5 | X35: 56 | Z35: =U35-X35 -> -56
A36: 115/02/14 | B36: 調劑 | F36: 15.5 | H36: =H35-F36 -> 884 | X36: 8 | Z36: =U36-X36 -> -8
A37: 115/02/15 | B37: 調劑 | F37: 4 | H37: =H36-F37 -> 880 | X37: 3 | Z37: =U37-X37 -> -3
A38: 115/02/16 | B38: 調劑 | F38: 2.5 | H38: =H37-F38 -> 877.5 | X38: 20 | Z38: =U38-X38 -> -20
A39: 115/02/23 | B39: 調劑 | F39: 86 | H39: =H38-F39 -> 791.5 | X39: 75.5 | Z39: =U39-X39 -> -75.5
A40: 115/02/25 | B40: 購買 | C40: 1500 | D40: E39013E1 | H40: 2291.5 | I40: 大昌ADP09400000704 | X40: 33 | Z40: =U40-X40 -> -33
...

Sheet 19
A1: 【 醫療機構、藥局 】(第 四 級管制藥品) | J1: 大昌華嘉ADP09400000703 | K1: 調劑 | L1: 購買
A2: 藥代：STI1/STI3/ STI4 | B2: 管 制 藥 品 收 支 結 存 簿 冊 | J2: 名稱 | K2: 字號 | L2: 上期結存 | M2: 收入 | N2: 支出 | O2: 結存
A3: 藥品名稱 | B3: Stilnox 10mg | E3: 管制藥品成分及含量 | H3: Zolpidem 10mg | J3: =B3 -> Stilnox 10mg | K3: 021531 | L3: =H7 -> 505.5 | M3: =SUM(C$8:C$1048576) -> 3024 | N3: =SUM(F:F) -> 1760 | O3: =L3+M3-N3 -> 1769.5
A4: 管制級別 | B4: 四 | E4: 製造廠名稱 | H4: 台灣安斯泰來製藥股份有限公司
A5: 藥品許可證字號 | C5: 衛署藥輸字第021531號 | H5: 最小單位 | I5: 粒
A6: 日 期 | B6: 收支原因 | C6: 收入數量 | D6: 收入藥品批號 | F6: 支出數量 | H6: 結存數量 | I6: 備 註
A7: 115/01/01 | B7: 上期結存 | C7: 505.5 | H7: 505.5 | I7: 維元社區藥局 (BPP112000001)
A8: 115/01/01 | B8: 調劑 | F8: 30 | H8: =H7-F8 -> 475.5
A9: 115/01/03 | B9: 調劑 | F9: 14 | H9: =H8-F9 -> 461.5
A10: 115/01/05 | B10: 調劑 | F10: 30 | H10: =H9-F10 -> 431.5
A11: 115/01/07 | B11: 調劑 | F11: 28 | H11: =H10-F11 -> 403.5
A12: 115/01/08 | B12: 購買 | C12: 1512 | D12: LT0509 | H12: 1915.5 | I12: 大昌
A13: 115/01/13 | B13: 調劑 | F13: 56 | H13: =H12-F13 -> 1859.5
A14: 115/01/15 | B14: 調劑 | F14: 28 | H14: =H13-F14 -> 1831.5
A15: 115/01/19 | B15: 調劑 | F15: 14 | H15: =H14-F15 -> 1817.5
A16: 115/02/01 | B16: 調劑 | F16: 30 | H16: =H15-F16 -> 1787.5
A17: 115/02/02 | B17: 調劑 | F17: 14 | H17: =H16-F17 -> 1773.5
A18: 115/02/03 | B18: 調劑 | F18: 30 | H18: =H17-F18 -> 1743.5
A19: 115/02/04 | B19: 調劑 | F19: 58 | H19: =H18-F19 -> 1685.5 | I19: 大昌華嘉ADP09400000704
A20: 115/02/14 | B20: 調劑 | F20: 42 | H20: =H19-F20 -> 1643.5
A21: 115/02/24 | B21: 調劑 | F21: 35 | H21: =H20-F21 -> 1608.5
A22: 115/02/25 | B22: 調劑 | F22: 30 | H22: =H21-F22 -> 1578.5
A23: 115/02/28 | B23: 調劑 | F23: 7 | H23: =H22-F23 -> 1571.5
A24: 115/03/01 | B24: 調劑 | F24: 30 | H24: =H23-F24 -> 1541.5
A25: 115/03/02 | B25: 調劑 | F25: 14 | H25: =H24-F25 -> 1527.5
A26: 115/03/05 | B26: 調劑 | F26: 28 | H26: =H25-F26 -> 1499.5
A27: 115/03/06 | B27: 調劑 | F27: 30 | H27: =H26-F27 -> 1469.5
A28: 115/03/10 | B28: 調劑 | F28: 15 | H28: =H27-F28 -> 1454.5
A29: 115/03/11 | B29: 調劑 | F29: 56 | H29: =H28-F29 -> 1398.5
A30: 115/03/13 | B30: 調劑 | F30: 30 | H30: =H29-F30 -> 1368.5
A31: 115/03/15 | B31: 調劑 | F31: 28 | H31: =H30-F31 -> 1340.5
... A46: 115/05/06 | B46: 調劑 | F46: 30 | H46: =H45-F46 -> 959.5
A47: 115/05/06 | B47: 購買 | C47: 1512 | D47: LT1177 | H47: 2471.5 | I47: 大昌ADP09400000704
A48: 115/05/07 | B48: 調劑 | F48: 28 | H48: =H47-F48 -> 2443.5
A49: 115/05/11 | B49: 調劑 | F49: 14 | H49: =H48-F49 -> 2429.5
A50: 115/05/15 | B50: 調劑 | F50: 28 | H50: =H49-F50 -> 2401.5
A51: 115/05/19 | B51: 調劑 | F51: 30 | H51: =H50-F51 -> 2371.5
A52: 115/05/25 | B52: 調劑 | F52: 14 | H52: =H51-F52 -> 2357.5
A53: 115/06/01 | B53: 調劑 | F53: 114 | H53: =H52-F53 -> 2243.5
A54: 115/06/03 | B54: 調劑 | F54: 30 | H54: =H53-F54 -> 2213.5
...

Sheet 20
A1: 【 醫療機構、藥局 】(第 四 級管制藥品)
A2: 藥代：ULTR | B2: 管 制 藥 品 收 支 結 存 簿 冊 | J2: 名稱 | K2: 字號 | L2: 上期結存 | M2: 收入 | N2: 支出 | O2: 結存
A3: 藥品名稱 | B3: Ultracet 37.5mg | E3: 管制藥品成分及含量 | H3: Tramadol 37.5mg / Acetaminophen 325mg | J3: =B3 -> Ultracet 37.5mg | K3: 023917 | L3: 0 | M3: =SUM(C:C) -> 0 | N3: =SUM(F:F) -> 0 | O3: =L3+M3-N3 -> 0
A4: 管制級別 | B4: 四 | E4: 製造廠名稱 | H4: 嬌生股份有限公司
A5: 藥品許可證字號 | C5: 衛署藥輸字第023917號 | H5: 最小單位 | I5: 粒
A6: 日 期 | B6: 收支原因 | C6: 收入數量 | D6: 收入藥品批號 | F6: 支出數量 | H6: 結存數量 | I6: 備 註
A7: 115/01/01 | B7: 上期結存 | C7: 0 | H7: 0

Sheet 21
A1: 【 醫療機構、藥局 】(第 四 級管制藥品)
A2: 藥代：XAN1/XAN2 | B2: 管 制 藥 品 收 支 結 存 簿 冊 | J2: 名稱 | K2: 字號 | L2: 上期結存 | M2: 收入 | N2: 支出 | O2: 結存
A3: 藥品名稱 | B3: Xanax 0.5mg | E3: 管制藥品成分及含量 | H3: Alprazolam 0.5mg | J3: =B3 -> Xanax 0.5mg | K3: 021140 | L3: =H7 -> 1402 | M3: =SUM(C$8:C$1048576) -> 3000 | N3: =SUM(F:F) -> 2951 | O3: =L3+M3-N3 -> 1451
A4: 管制級別 | B4: 四 | E4: 製造廠名稱 | H4: 暉致醫藥股份有限公司
A5: 藥品許可證字號 | C5: 衛署藥輸字第021140號 | H5: 最小單位 | I5: 粒
A6: 日 期 | B6: 收支原因 | C6: 收入數量 | D6: 收入藥品批號 | F6: 支出數量 | H6: 結存數量 | I6: 備 註
A7: 115/01/01 | B7: 上期結存 | C7: 1402 | H7: 1402 | I7: 維元社區藥局 (BPP112000001) | Q7: 使用日期 | R7: 藥代 | S7: 消耗量
A8: 115/01/03 | B8: 調劑 | F8: 3 | H8: =H7-F8 -> 1399
A9: 115/01/05 | B9: 調劑 | F9: 56 | H9: =H8-F9 -> 1343
A10: 115/01/06 | B10: 調劑 | F10: 56 | H10: =H9-F10 -> 1287
A11: 115/01/07 | B11: 調劑 | F11: 30 | H11: =H10-F11 -> 1257
A12: 115/01/08 | B12: 調劑 | F12: 56 | H12: =H11-F12 -> 1201
A13: 115/01/13 | B13: 調劑 | F13: 59 | H13: =H12-F13 -> 1142
A14: 115/01/14 | B14: 調劑 | F14: 61 | H14: =H13-F14 -> 1081
A15: 115/01/22 | B15: 調劑 | F15: 56 | H15: =H14-F15 -> 1025
A16: 115/01/23 | B16: 調劑 | F16: 58 | H16: =H15-F16 -> 967
A17: 115/01/28 | B17: 調劑 | F17: 14 | H17: =H16-F17 -> 953
A18: 115/01/30 | B18: 調劑 | F18: 28 | H18: =H17-F18 -> 925
A19: 115/02/04 | B19: 調劑 | F19: 30 | H19: =H18-F19 -> 895
... A28: 115/02/25 | B28: 調劑 | F28: 30 | H28: =H27-F28 -> 515
A29: 115/02/25 | B29: 購買 | C29: 1500 | D29: MT3220 | H29: 2015 | I29: 久裕CDP10300000803
A30: 115/02/26 | B30: 調劑 | F30: 3 | H30: =H29-F30 -> 2012
A31: 115/03/03 | B31: 調劑 | F31: 56 | H31: =H30-F31 -> 1956
A32: 115/03/06 | B32: 調劑 | F32: 61 | H32: =H31-F32 -> 1895
A33: 115/03/10 | B33: 調劑 | F33: 30 | H33: =H32-F33 -> 1865
A34: 115/03/11 | B34: 調劑 | F34: 84 | H34: =H33-F34 -> 1781
A35: 115/03/12 | B35: 調劑 | F35: 56 | H35: =H34-F35 -> 1725
A36: 115/03/13 | B36: 調劑 | F36: 59 | H36: =H35-F36 -> 1666
A37: 115/03/19 | B37: 調劑 | F37: 30 | H37: =H36-F37 -> 1636
A38: 115/03/21 | B38: 調劑 | F38: 86 | H38: =H37-F38 -> 1550
A39: 115/03/23 | B39: 調劑 | F39: 42 | H39: =H38-F39 -> 1508
A40: 115/03/24 | B40: 調劑 | F40: 59 | H40: =H39-F40 -> 1449
A41: 115/03/31 | B41: 調劑 | F41: 6 | H41: =H40-F41 -> 1443
... A45: 115/04/13 | B45: 調劑 | F45: 30 | H45: =H44-F45 -> 1242
A46: 115/04/17 | B46: 調劑 | F46: 56 | H46: =H45-F46 -> 1186 | I46: 久裕CDP10300000803
A47: 115/04/28 | B47: 調劑 | F47: 28 | H47: =H46-F47 -> 1158
A48: 115/04/29 | B48: 調劑 | F48: 56 | H48: =H47-F48 -> 1102
A49: 115/05/01 | B49: 調劑 | F49: 30 | H49: =H48-F49 -> 1072
A50: 115/05/07 | B50: 調劑 | F50: 56 | H50: =H49-F50 -> 1016
A51: 115/05/09 | B51: 調劑 | F51: 56 | H51: =H50-F51 -> 960
...

Sheet 22
A1: 【 醫療機構、藥局 】(第 四 級管制藥品)
A2: 藥代：APO0 | B2: 管 制 藥 品 收 支 結 存 簿 冊 | J2: 名稱 | K2: 字號 | L2: 上期結存 | M2: 收入 | N2: 支出 | O2: 結存
A3: 藥品名稱 | B3: Apo-Tramadol 37.5mg/ 325mg | E3: 管制藥品成分及含量 | H3: Tramadol 37.5mg / Acetaminophen 325mg | J3: =B3 -> Apo-Tramadol 37.5mg/ 325mg | K3: 025452 | L3: =H7 -> 140 | M3: =SUM(C$8:C$1048576) -> 800 | N3: =SUM(F:F) -> 956 | O3: =L3+M3-N3 -> -16
A4: 管制級別 | B4: 四 | E4: 製造廠名稱 | H4: 鴻汶醫藥實業有限公司
A5: 藥品許可證字號 | C5: 衛署藥輸字第025452號 | H5: 最小單位 | I5: 粒
A6: 日 期 | B6: 收支原因 | C6: 收入數量 | D6: 收入藥品批號 | F6: 支出數量 | H6: 結存數量 | I6: 備 註
A7: 115/01/01 | B7: 上期結存 | C7: 140 | H7: 140 | I7: 維元社區藥局 (BPP112000001)
A8: 115/01/04 | B8: 購買 | C8: 200 | D8: VJ0629 | H8: 340 | I8: 嘉鏵CDP100000003
A9: 115/01/14 | B9: 調劑 | F9: 56 | H9: =H8-F9 -> 284
A10: 115/01/15 | B10: 調劑 | F10: 56 | H10: =H9-F10 -> 228
A11: 115/01/31 | B11: 調劑 | F11: 12 | H11: =H10-F11 -> 216 | I11: 嘉鏵CDP100000003
A12: 115/02/06 | B12: 調劑 | F12: 56 | H12: =H11-F12 -> 160
A13: 115/02/07 | B13: 調劑 | F13: 56 | H13: =H12-F13 -> 104
A14: 115/02/25 | B14: 購買 | D14: VJ0630 | H14: 304 | I14: 嘉鏵CDP100000003
A15: 115/03/13 | B15: 調劑 | F15: 56 | H15: =H14-F15 -> 248
A16: 115/03/14 | B16: 調劑 | F16: 12 | H16: =H15-F16 -> 236 | I16: 嘉鏵
A17: 115/03/28 | B17: 調劑 | F17: 12 | H17: =H16-F17 -> 224
A18: 115/04/09 | B18: 調劑 | F18: 112 | H18: =H17-F18 -> 112
A19: 115/04/22 | B19: 購買 | C19: 400 | D19: VJ4597 | H19: 512 | I19: 嘉鏵CDP100000003
A20: 115/04/27 | B20: 調劑 | F20: 56 | H20: =H19-F20 -> 456
A21: 115/05/02 | B21: 調劑 | F21: 56 | H21: =H20-F21 -> 400
A22: 115/05/09 | B22: 調劑 | F22: 68 | H22: =H21-F22 -> 332 | I22: 嘉鏵CDP100000003
A23: 115/05/20 | B23: 調劑 | F23: 56 | H23: =H22-F23 -> 276 | I23: 嘉鏵
A24: 115/06/08 | B24: 調劑 | F24: 56 | H24: =H23-F24 -> 220
A25: 115/06/13 | B25: 調劑 | F25: 56 | H25: =H24-F25 -> 164
A26: 115/06/27 | B26: 調劑 | F26: 56 | H26: =H25-F26 -> 108
A27: 115/07/05 | B27: 購買 | C27: 200 | D27: VR4858 | H27: 308 | I27: 嘉鏵CDP100000003
A28: 115/07/18 | B28: 調劑 | F28: 12 | H28: =H27-F28 -> 296
A29: 115/07/22 | B29: 調劑 | F29: 112 | H29: =H28-F29 -> 184
I30: 嘉鏵
I31: 嘉鏵
I32: 嘉鏵
I37: 嘉鏵

Sheet 23
A1: 【 醫療機構、藥局 】(第 四 級管制藥品) | J1: 大昌華嘉(ADP09400000703) | K1: 調劑 | L1: 購買
A2: 藥代：RIV3/RIV5 | B2: 管 制 藥 品 收 支 結 存 簿 冊 | J2: 名稱 | K2: 字號 | L2: 上期結存 | M2: 收入 | N2: 支出 | O2: 結存
A3: 藥品名稱 | B3: Rivotril 2mg | E3: 管制藥品成分及含量 | H3: Clonazepam 2mg | J3: =B3 -> Rivotril 2mg | K3: 003078 | L3: =H7 -> 206.5 | M3: =SUM(C$8:C$1048576) -> 1200 | N3: =SUM(F:F) -> 664 | O3: =L3+M3-N3 -> 742.5
A4: 管制級別 | B4: 四 | E4: 製造廠名稱 | H4: 羅氏大製藥有限股份公司
A5: 藥品許可證字號 | C5: 衛署藥輸字第003078號 | H5: 最小單位 | I5: 粒
A6: 日 期 | B6: 收支原因 | C6: 收入數量 | D6: 收入藥品批號 | F6: 支出數量 | H6: 結存數量 | I6: 備 註
A7: 115/01/01 | B7: 上期結存 | C7: 206.5 | H7: 206.5 | I7: 維元社區藥局 (BPP103000001)
A8: 115/1/14 | B8: 調劑 | F8: 28 | H8: =H7-F8 -> 178.5
A9: 115/01/21 | B9: 調劑 | F9: 28 | H9: =H8-F9 -> 150.5 | I9: 大昌
A10: 115/01/30 | B10: 調劑 | F10: 14 | H10: =H9-F10 -> 136.5
A11: 115/02/07 | B11: 調劑 | F11: 47 | H11: =H10-F11 -> 89.5
A12: 115/02/13 | B12: 調劑 | F12: 28 | H12: =H11-F12 -> 61.5
A13: 115/02/25 | B13: 購買 | C13: 600 | D13: E2747E1 | H13: 661.5 | I13: 大昌ADP09400000704
A14: 115/03/06 | B14: 調劑 | F14: 14 | H14: =H13-F14 -> 647.5
A15: 115/03/13 | B15: 調劑 | F15: 75 | H15: =H14-F15 -> 572.5
A16: 115/03/23 | B16: 調劑 | F16: 14 | H16: =H15-F16 -> 558.5
A17: 115/03/24 | B17: 調劑 | F17: 28 | H17: =H16-F17 -> 530.5
A18: 115/04/09 | B18: 調劑 | F18: 28 | H18: =H17-F18 -> 502.5
A19: 115/04/26 | B19: 調劑 | F19: 56 | H19: =H18-F19 -> 446.5
A20: 115/04/27 | B20: 購買 | C20: 600 | D20: E2754E1 | H20: =H19+C20 -> 1046.5 | I20: 大昌華嘉
A21: 115/04/28 | B21: 調劑 | F21: 14 | H21: =H20-F21 -> 1032.5
A22: 115/05/13 | B22: 調劑 | F22: 28 | H22: =H21-F22 -> 1004.5
A23: 115/05/15 | B23: 調劑 | F23: 28 | H23: =H22-F23 -> 976.5
A24: 115/06/01 | B24: 調劑 | F24: 14 | H24: =H23-F24 -> 962.5
A25: 115/06/02 | B25: 調劑 | F25: 47 | H25: =H24-F25 -> 915.5
A26: 115/06/10 | B26: 調劑 | F26: 28 | H26: =H25-F26 -> 887.5
A27: 115/06/26 | B27: 調劑 | F27: 47 | H27: =H26-F27 -> 840.5
A28: 115/07/08 | B28: 調劑 | F28: 28 | H28: =H27-F28 -> 812.5
A29: 115/07/13 | B29: 調劑 | F29: 28 | H29: =H28-F29 -> 784.5
A30: 115/07/14 | B30: 調劑 | F30: 28 | H30: =H29-F30 -> 756.5
A31: 115/07/23 | B31: 調劑 | F31: 14 | H31: =H30-F31 -> 742.5

Sheet 24
A1: 【 醫療機構、藥局 】(第 四 級管制藥品) | J1: 嘉鏵CDP100000003 | K1: 江鎰(QDA10600000101) | L1: 調劑 | M1: 購買
A2: 藥代： IMO2/IMO3 | B2: 管 制 藥 品 收 支 結 存 簿 冊 | J2: 名稱 | K2: 字號 | L2: 上期結存 | M2: 收入 | N2: 支出 | O2: 結存
A3: 藥品名稱 | B3: Imovane 7.5mg | E3: 管制藥品成分及含量 | H3: Zopiclone 7.5mg | J3: =B3 -> Imovane 7.5mg | K3: 018158 | L3: =H7 -> 323 | M3: =SUM(C$8:C$1048576) -> 1680 | N3: =SUM(F:F) -> 1566.5 | O3: =L3+M3-N3 -> 436.5
A4: 管制級別 | B4: 四 | E4: 製造廠名稱 | H4: 賽諾菲股份有限公司
A5: 藥品許可證字號 | C5: 衛署藥輸字第018158號 | H5: 最小單位 | I5: 粒
A6: 日 期 | B6: 收支原因 | C6: 收入數量 | D6: 收入藥品批號 | F6: 支出數量 | H6: 結存數量 | I6: 備 註
A7: 115/01/01 | B7: 上期結存 | C7: 323 | H7: 323 | I7: 維元社區藥局 (BPP112000001)
A8: 115/01/01 | B8: 調劑 | F8: 30 | H8: =H7-F8 -> 293
A9: 115/01/02 | B9: 調劑 | F9: 30 | H9: =H8-F9 -> 263
A10: 115/01/05 | B10: 調劑 | F10: 28 | H10: =H9-F10 -> 235
A11: 115/01/07 | B11: 調劑 | F11: 28 | H11: =H10-F11 -> 207
A12: 115/01/09 | B12: 調劑 | F12: 28 | H12: =H11-F12 -> 179
A13: 115/01/10 | B13: 購買 | C13: 280 | D13: 5M96D | H13: 459 | I13: QDA10600000101 江鎰
A14: 115/01/19 | B14: 調劑 | F14: 30 | H14: =H13-F14 -> 429
A15: 115/01/30 | B15: 調劑 | F15: 58 | H15: =H14-F15 -> 371
A16: 115/02/02 | B16: 調劑 | F16: 30 | H16: =H15-F16 -> 341
A17: 115/02/03 | B17: 調劑 | F17: 28 | H17: =H16-F17 -> 313
A18: 115/02/05 | B18: 調劑 | F18: 28 | H18: =H17-F18 -> 285
A19: 115/02/21 | B19: 調劑 | F19: 28 | H19: =H18-F19 -> 257
A20: 115/03/02 | B20: 調劑 | F20: 60 | H20: =H19-F20 -> 197
A21: 115/03/04 | B21: 調劑 | F21: 56 | H21: =H20-F21 -> 141
A22: 115/03/06 | B22: 購買 | C22: 280 | D22: 5PX2D | H22: 421 | I22: 嘉鏵
A23: 115/03/11 | B23: 調劑 | F23: 30 | H23: =H22-F23 -> 391
A24: 115/03/13 | B24: 調劑 | F24: 14 | H24: =H23-F24 -> 377
A25: 115/03/18 | B25: 調劑 | F25: 56 | H25: =H24-F25 -> 321
A26: 115/03/24 | B26: 調劑 | F26: 14 | H26: =H25-F26 -> 307
A27: 115/03/26 | B27: 調劑 | F27: 42 | H27: =H26-F27 -> 265
A28: 115/03/28 | B28: 調劑 | F28: 30 | H28: =H27-F28 -> 235
A29: 115/03/30 | B29: 調劑 | F29: 58 | H29: =H28-F29 -> 177 | I29: 嘉鏵
A30: 115/04/01 | B30: 調劑 | F30: 58 | H30: =H29-F30 -> 119
A31: 115/04/02 | B31: 調劑 | F31: 28 | H31: =H30-F31 -> 91
A32: 115/04/07 | B32: 購買 | C32: 280 | D32: 5PX2D | H32: 371 | I32: 嘉鏵
A33: 115/04/14 | B33: 調劑 | F33: 56 | H33: =H32-F33 -> 315
A34: 115/04/16 | B34: 調劑 | F34: 28 | H34: =H33-F34 -> 287
A35: 115/04/22 | B35: 調劑 | F35: 1.5 | H35: =H34-F35 -> 285.5
A36: 115/04/24 | B36: 調劑 | F36: 3 | H36: =H35-F36 -> 282.5 | I36: 嘉鏵
A37: 115/04/30 | B37: 調劑 | F37: 28 | H37: =H36-F37 -> 254.5
A38: 115/05/01 | B38: 調劑 | F38: 30 | H38: =H37-F38 -> 224.5
A39: 115/05/03 | B39: 購買 | C39: 280 | D39: 5PX2G | H39: 504.5 | I39: 嘉鏵CDP100000003
A40: 115/05/04 | B40: 調劑 | F40: 7 | H40: =H39-F40 -> 497.5
...

Sheet 25
A1: 【 醫療機構、藥局 】(第 四 級管制藥品)
A2: 藥代：STIL/SEM | B2: 管 制 藥 品 收 支 結 存 簿 冊 | J2: 名稱 | K2: 字號 | L2: 上期結存 | M2: 收入 | N2: 支出 | O2: 結存
A3: 藥品名稱 | B3: Semi-Nax 10mg | E3: 管制藥品成分及含量 | H3: Zolpidem 10mg | J3: =B3 -> Semi-Nax 10mg | K3: 044463 | L3: =H7 -> 107 | M3: =SUM(C$8:C$1048576) -> 750 | N3: =SUM(F:F) -> 690 | O3: =L3+M3-N3 -> 167
A4: 管制級別 | B4: 四 | E4: 製造廠名稱 | H4: 鼎泰藥品股份有限公司
A5: 藥品許可證字號 | C5: 衛署藥製字第044463號 | H5: 最小單位 | I5: 粒
A6: 日 期 | B6: 收支原因 | C6: 收入數量 | D6: 收入藥品批號 | F6: 支出數量 | H6: 結存數量 | I6: 備 註
A7: 115/01/01 | B7: 上期結存 | C7: 107 | H7: 107 | I7: 維元社區藥局 (BPP112000001)
A8: 115/01/12 | B8: 調劑 | F8: 30 | H8: =H7-F8 -> 77 | I8: 嘉鏵
A9: 115/01/21 | B9: 調劑 | F9: 56 | H9: =H8-F9 -> 21 | I9: 7/31王麗晴
A10: 115/01/23 | B10: 購買 | C10: 100 | D10: 2J5301 | H10: 121 | I10: 嘉鏵CDP100000003
A11: 115/02/04 | B11: 調劑 | F11: 56 | H11: =H10-F11 -> 65
A12: 115/02/05 | B12: 購買 | C12: 100 | D12: 2J5301 | H12: 165 | I12: 嘉鏵CDP100000003
A13: 115/02/05 | B13: 購買 | C13: 60 | D13: 2E5301 | H13: =H12+C13 -> 225 | I13: 江鎰QDA10600000101
A14: 115/02/06 | B14: 購買 | C14: 40 | D14: 2E5301 | H14: =H13+C14 -> 265 | I14: 江鎰QDA10600000101
A15: 115/02/06 | B15: 調劑 | F15: 28 | H15: =H14-F15 -> 237
A16: 115/02/09 | B16: 購買 | C16: 50 | D16: 2E5301 | H16: 287 | I16: 江鎰QDA10600000101
A17: 115/02/09 | B17: 調劑 | F17: 30 | H17: =H16-F17 -> 257
A18: 115/02/26 | B18: 調劑 | F18: 70 | H18: =H17-F18 -> 187 | I18: 江鎰QDA10600000101
A19: 115/03/05 | B19: 調劑 | F19: 28 | H19: =H18-F19 -> 159
A20: 115/03/24 | B20: 調劑 | F20: 56 | H20: =H19-F20 -> 103
A21: 115/04/11 | B21: 調劑 | F21: 28 | H21: =H20-F21 -> 75
A22: 115/04/15 | B22: 購買 | C22: 100 | D22: 2K5301 | H22: 175 | I22: 嘉鏵CDP100000003
A23: 115/04/24 | B23: 調劑 | F23: 28 | H23: =H22-F23 -> 147
A24: 115/05/08 | B24: 調劑 | F24: 28 | H24: =H23-F24 -> 119
A25: 115/05/11 | B25: 調劑 | F25: 28 | H25: =H24-F25 -> 91
A26: 115/05/13 | B26: 購買 | C26: 220 | D26: 2A6301 | H26: 311 | I26: 江鎰QDA10600000101
A27: 115/05/13 | B27: 購買 | C27: 80 | D27: 2J5302 | H27: 391 | I27: 江鎰QDA10600000101
A28: 115/05/15 | B28: 調劑 | F28: 56 | H28: =H27-F28 -> 335
A29: 115/05/25 | B29: 調劑 | F29: 28 | H29: =H28-F29 -> 307
A30: 115/06/06 | B30: 調劑 | F30: 28 | H30: =H29-F30 -> 279
A31: 115/07/07 | B31: 調劑 | F31: 28 | H31: =H30-F31 -> 251
A32: 115/07/13 | B32: 調劑 | F32: 56 | H32: =H31-F32 -> 195
A33: 115/07/18 | B33: 調劑 | F33: 28 | H33: =H32-F33 -> 167

Sheet 26
A2: 藥代：CON2 | B2: 管 制 藥 品 收 支 結 存 簿 冊 | J2: 名稱 | K2: 字號 | L2: 上期結存 | M2: 收入 | N2: 支出 | O2: 結存
A3: 藥品名稱 | B3: Concerta E.R 18mg | E3: 管制藥品成分及含量 | H3: Methylphenidate 18mg | J3: =B3 -> Concerta E.R 18mg | K3: 023731 | L3: =H7 -> 26 | M3: =SUM(C$8:C$1048576) -> 120 | N3: =SUM(F:F) -> 120 | O3: =L3+M3-N3 -> 26
A4: 管制級別 | B4: 三 | E4: 製造廠名稱 | H4: 嬌生股份有限公司
A5: 藥品許可證字號 | C5: 衛署藥輸字第023731號 | H5: 最小單位 | I5: 粒
A6: 日 期 | B6: 收支原因 | C6: 收入數量 | D6: 收入藥品批號 | F6: 支出數量 | H6: 結存數量 | I6: 備 註
A7: 115/01/01 | B7: 上期結存 | C7: 26 | H7: 26 | I7: 維元社區藥局 (BPP112000001)
A8: 115/01/08 | B8: 購買 | C8: 30 | D8: 25KG125 | H8: 56 | I8: 嘉鏵
A9: 115/01/16 | B9: 調劑 | F9: 30 | H9: =H8-F9 -> 26 | I9: 于陳安
A10: 115/01/18 | B10: 購買 | C10: 30 | D10: 25KG125 | H10: 56 | I10: 嘉鏵CDP100000003
A11: 115/02/11 | B11: 調劑 | F11: 30 | H11: =H10-F11 -> 26 | I11: 于陳安
A12: 115/04/07 | B12: 購買 | C12: 30 | D12: 26AG392X | H12: 56 | I12: 嘉鏵
A13: 115/04/11 | B13: 調劑 | F13: 30 | H13: =H12-F13 -> 26 | I13: 于陳安
A14: 115/04/19 | B14: 購買 | C14: 30 | D14: 26AG392X | H14: 56 | I14: 嘉鏵CDP100000003
A15: 115/05/06 | B15: 調劑 | F15: 30 | H15: =H14-F15 -> 26 | I15: 于陳安

Sheet 27
A1: 【 醫療機構、藥局 】(第 三 級管制藥品)
A2: 藥代：APO1 | B2: 管 制 藥 品 收 支 結 存 簿 冊 | J2: 名稱 | K2: 字號 | L2: 上期結存 | M2: 收入 | N2: 支出 | O2: 結存
A3: 藥品名稱 | B3: Apo-Methyphenidate 10mg | E3: 管制藥品成分及含量 | H3: Methyphenidate 10mg | J3: =B3 -> Apo-Methyphenidate 10mg | K3: 025016 | L3: 0 | M3: =SUM(C:C) -> 0 | N3: =SUM(F:F) -> 0 | O3: =L3+M3-N3 -> 0
A4: 管制級別 | B4: 三 | E4: 製造廠名稱 | H4: 鴻汶醫藥實業有限公司
A5: 藥品許可證字號 | C5: 衛署藥輸字第025016號 | H5: 最小單位 | I5: 粒
A6: 日 期 | B6: 收支原因 | C6: 收入數量 | D6: 收入藥品批號 | F6: 支出數量 | H6: 結存數量 | I6: 備 註
A7: 115/01/01 | B7: 上期結存 | C7: 0 | H7: 0

Sheet 28
A2: 藥代：CON3 | B2: 管 制 藥 品 收 支 結 存 簿 冊 | J2: 名稱 | K2: 字號 | L2: 上期結存 | M2: 收入 | N2: 支出 | O2: 結存
A3: 藥品名稱 | B3: Concerta E.R 36mg | E3: 管制藥品成分及含量 | H3: Methylphenidate 36mg | J3: =B3 -> Concerta E.R 36mg | K3: 042646 | L3: =H7 -> 0 | M3: =SUM(C$7:C$1048576) -> 120 | N3: =SUM(F:F) -> 120 | O3: =L3+M3-N3 -> 0
A4: 管制級別 | B4: 三 | E4: 製造廠名稱 | H4: 嬌生股份有限公司
A5: 藥品許可證字號 | C5: 衛署藥輸字第023880號 | H5: 最小單位 | I5: 粒
A6: 日 期 | B6: 收支原因 | C6: 收入數量 | D6: 收入藥品批號 | F6: 支出數量 | H6: 結存數量 | I6: 備 註
A7: 115/01/01 | B7: 上期結存 | C7: 0 | H7: 0 | I7: 維元社區藥局 (BPP112000001)
A8: 115/01/08 | B8: 購買 | C8: 30 | D8: 25gg843 | H8: 30 | I8: 嘉鏵
A9: 115/01/16 | B9: 調劑 | F9: 30 | H9: =H8-F9 -> 0 | I9: 于陳安
A10: 115/01/18 | B10: 購買 | C10: 30 | D10: 25GG843 | H10: 30 | I10: 嘉鏵CDP10000003
A11: 115/02/11 | B11: 調劑 | F11: 30 | H11: =H10-F11 -> 0 | I11: 于陳安
A12: 115/04/07 | B12: 購買 | C12: 60 | D12: 25LG189 | H12: 60 | I12: 嘉鏵
A13: 115/04/11 | B13: 調劑 | F13: 30 | H13: =H12-F13 -> 30 | I13: 于陳安
A14: 115/05/06 | B14: 調劑 | F14: 30 | H14: =H13-F14 -> 0 | I14: 于陳安

Sheet 29
A1: 【 醫療機構、藥局 】(第 四 級管制藥品)
A2: 藥代：ALPR4/ALP1 | B2: 管 制 藥 品 收 支 結 存 簿 冊 | J2: 名稱 | K2: 字號 | L2: 上期結存 | M2: 收入 | N2: 支出 | O2: 結存
A3: 藥品名稱 | B3: Alprazolam 0.5mg | E3: 管制藥品成分及含量 | H3: Alprazolam 0.5mg | J3: =B3 -> Alprazolam 0.5mg | K3: 057740 | L3: =H7 -> 1383.5 | M3: =SUM(C$8:C$1048576) -> 6000 | N3: =SUM(F:F) -> 5451 | O3: =L3+M3-N3 -> 1932.5
A4: 管制級別 | B4: 四 | E4: 製造廠名稱 | H4: 中化裕民健康事業股份有限公司
A5: 藥品許可證字號 | C5: 衛署藥製字第057740號 | H5: 最小單位 | I5: 粒
A6: 日 期 | B6: 收支原因 | C6: 收入數量 | D6: 收入藥品批號 | F6: 支出數量 | H6: 結存數量 | I6: 備 註
A7: 115/01/01 | B7: 上期結存 | C7: 1383.5 | H7: 1383.5 | I7: 維元社區藥局 (BPP112000001)
A8: 115/01/02 | B8: 調劑 | F8: 34.5 | H8: =H7-F8 -> 1349
A9: 115/01/03 | B9: 調劑 | F9: 18 | H9: =H8-F9 -> 1331
A10: 115/01/04 | B10: 調劑 | F10: 30 | H10: =H9-F10 -> 1301
A11: 115/01/05 | B11: 調劑 | F11: 96 | H11: =H10-F11 -> 1205
A12: 115/01/06 | B12: 調劑 | F12: 28 | H12: =H11-F12 -> 1177
A13: 115/01/08 | B13: 調劑 | F13: 4.5 | H13: =H12-F13 -> 1172.5
A14: 115/01/09 | B14: 調劑 | F14: 60 | H14: =H13-F14 -> 1112.5
A15: 115/01/11 | B15: 調劑 | F15: 4.5 | H15: =H14-F15 -> 1108
A16: 115/01/12 | B16: 調劑 | F16: 14 | H16: =H15-F16 -> 1094
A17: 115/01/14 | B17: 調劑 | F17: 4.5 | H17: =H16-F17 -> 1089.5
A18: 115/01/15 | B18: 調劑 | F18: 28 | H18: =H17-F18 -> 1061.5
A19: 115/01/16 | B19: 調劑 | F19: 71 | H19: =H18-F19 -> 990.5
... A23: 115/01/21 | B23: 調劑 | F23: 63 | H23: =H22-F23 -> 810.5
A24: 115/01/23 | B24: 購買 | C24: 2000 | D24: C1230222 | H24: 2810.5 | I24: 中化
A25: 115/01/23 | B25: 調劑 | F25: 7.5 | H25: =H24-F25 -> 2803
A26: 115/01/25 | B26: 調劑 | F26: 44 | H26: =H25-F26 -> 2759
A27: 115/01/26 | B27: 調劑 | F27: 7.5 | H27: =H26-F27 -> 2751.5
A28: 115/01/27 | B28: 調劑 | F28: 18 | H28: =H27-F28 -> 2733.5
A29: 115/01/28 | B29: 調劑 | F29: 30 | H29: =H28-F29 -> 2703.5
A30: 115/01/29 | B30: 調劑 | F30: 10.5 | H30: =H29-F30 -> 2693
A31: 115/01/30 | B31: 調劑 | F31: 89 | H31: =H30-F31 -> 2604
A32: 115/02/01 | B32: 調劑 | F32: 4.5 | H32: =H31-F32 -> 2599.5
A33: 115/02/02 | B33: 調劑 | F33: 21 | H33: =H32-F33 -> 2578.5
A34: 115/02/03 | B34: 調劑 | F34: 47 | H34: =H33-F34 -> 2531.5
A35: 115/02/04 | B35: 調劑 | F35: 4.5 | H35: =H34-F35 -> 2527
A36: 115/02/05 | B36: 調劑 | F36: 153 | H36: =H35-F36 -> 2374
... A40: 115/02/10 | B40: 調劑 | F40: 32.5 | H40: =H39-F40 -> 2261
A41: 115/02/12 | B41: 調劑 | F41: 75 | H41: =H40-F41 -> 2186 | I41: 中化ADP09200001603
A42: 115/02/13 | B42: 調劑 | F42: 32.5 | H42: =H41-F42 -> 2153.5
A43: 115/02/14 | B43: 調劑 | F43: 18 | H43: =H42-F43 -> 2135.5
A44: 115/02/15 | B44: 調劑 | F44: 80 | H44: =H43-F44 -> 2055.5
A45: 115/02/16 | B45: 調劑 | F45: 34.5 | H45: =H44-F45 -> 2021
A46: 115/02/21 | B46: 調劑 | F46: 4.5 | H46: =H45-F46 -> 2016.5
...

Sheet 30
A1: 【 醫療機構、藥局 】(第 四 級管制藥品)
A2: 藥代：DAC2 | B2: 管 制 藥 品 收 支 結 存 簿 冊 | J2: 名稱 | K2: 字號 | L2: 上期結存 | M2: 收入 | N2: 支出 | O2: 結存
A3: 藥品名稱 | B3: Dactive 10 mg | E3: 管制藥品成分及含量 | H3: Zolpidem 10mg | J3: =B3 -> Dactive 10 mg | K3: 024958 | L3: 0 | M3: =SUM(C:C) -> 0 | N3: =SUM(F:F) -> 0 | O3: =L3+M3-N3 -> 0
A4: 管制級別 | B4: 四 | E4: 製造廠名稱 | H4: 毅有生技醫藥股份有限公司
A5: 藥品許可證字號 | C5: 衛署藥輸字第024958號 | H5: 最小單位 | I5: 粒
A6: 日 期 | B6: 收支原因 | C6: 收入數量 | D6: 收入藥品批號 | F6: 支出數量 | H6: 結存數量 | I6: 備 註
A7: 115/01/01 | B7: 上期結存 | C7: 0 | H7: 0

Sheet 31
A1: 【 醫療機構、藥局 】(第 四 級管制藥品)
A2: 藥代：ALP2 | B2: 管 制 藥 品 收 支 結 存 簿 冊 | J2: 名稱 | K2: 字號 | L2: 上期結存 | M2: 收入 | N2: 支出 | O2: 結存
A3: 藥品名稱 | B3: Alpraline 0.5mg | E3: 管制藥品成分及含量 | H3: Alprazolam 0.5mg | J3: =B3 -> Alpraline 0.5mg | K3: 044685 | L3: =H7 -> 443 | M3: =SUM(C$8:C$1048576) -> 1000 | N3: =SUM(F:F) -> 903.5 | O3: =L3+M3-N3 -> 539.5
A4: 管制級別 | B4: 四 | E4: 製造廠名稱 | H4: 信東生技股份有限公司
A5: 藥品許可證字號 | C5: 衛署藥製字第044685號 | H5: 最小單位 | I5: 粒
A6: 日 期 | B6: 收支原因 | C6: 收入數量 | D6: 收入藥品批號 | F6: 支出數量 | H6: 結存數量 | I6: 備 註
